Workbook
Name çسçر76: [2]çسçرءهآس!$C$2:$J$39
Name çسçر76: [3]çسçرءهآس!$C$2:$J$39
Name çسçر76: [3]çسçرءهآس!$C$2:$J$39
Name بسوآهè: [2]çسçرءهآس!$CY$83:$DD$97
Name بسوآهè: [3]çسçرءهآس!$CY$83:$DD$97
Name بسوآهè: [3]çسçرءهآس!$CY$83:$DD$97
Name مشآسطçسçرهآèآوè: [2]çسçرءهآس!$T$6:$AA$23
Name مشآسطçسçرهآèآوè: [3]çسçرءهآس!$T$6:$AA$23
Name مشآسطçسçرهآèآوè: [3]çسçرءهآس!$T$6:$AA$23

Sheet IR
D2: ETc | E2: Ksp | F2: Kd | G2: Ksh | H2: Kmc | I2: IR; mm/d | J2: Kage | K2: Kstress | L2: Eff | M2: Lf | N2: Atree | O2: سهم ماه اوج | P2: ساعات کار | Q2: Ao | R2: lit/d | S2: m3/ha | T2: QHM
B3: سال خشک | D3: 7.1 | E3: 0.5 | F3: 1 | G3: =K20 -> 0.28117076 | H3: 1 | I3: =D3*E3*F3*H3 -> 3.55 | J3: 1 | K3: 0.65 | L3: 0.8 | M3: 0.05 | N3: 5 | O3: 0.22 | P3: 24 | Q3: 30 | R3: =+I3*Q3*G3/L3/(1-M3)*$J3*$K3 -> 25.610587 | S3: =R3/Q3*10*31/O3 -> 1202.9215 | T3: =R3/Q3/8.64*24/P3 -> 0.098806277
E4: برآورد نیازآبیاری و شدت جریان ماه اوج مصرف در کمربند سبز مشهد. | W4: انتخاب روش
B5: خارج از محدوده | D5: پهنه‌های کمربند سبز جنوبی | H5: وسعت پهنه | I5: سطح إسمی درختان | J5: درصد سایه‌انداز | K5: ضریب سایه‌انداز | L5: نیاز آبیاری روزانه | M5: نیاز هر درخت | N5: نیاز آبیاری سالانه | O5: آبدهی واحد (هیدرومدول) متوسط 9ماهه و ماه اوج | Q5: نیاز آبیاری سالانه | R5: آبدهی موردنیاز ماه اوج | U5: نیاز آبیاری سالانه | W5: 2 | X5: ناحیه | Y5: نیاز آبی با 20 ساعت پمپاژ (لیتر بر ثانیه) | Z5: مساحت (هکتار)
H6: ha | I6: m2 | J6: % | K6: Ksh | L6: mm/d | M6: lit/d | N6: m3/ha | O6: lit/s/ha | Q6: MCM | R6: lit/s | U6: m3/ha
B7: + | C7: =ک.ج2!V24 -> 2080.058 | D7: =ک.ج2!S24 -> نگهداری قدیم -زون 1 الی11 | H7: =ک.ج2!V24-21 -> 2059.058 | I7: =ک.ج2!R24 -> 37.165355 | J7: =N$3/I7 -> 0.13453389 | K7: =IF(W$5=1,(J7)^0.5,J7+15/100*(1-J7)) -> 0.26435381 | L7: =I$3*K7/L$3/(1-M$3)*$J$3*$K$3 -> 0.80262686 | M7: =+L7*I7 -> 29.829913 | N7: =ROUND(U7,-1) -> 1130 | O7: =L7/8.64*24/P$3 -> 0.092896628 | P7: =U7/((6*31+3*30)*24*3600)*1000 -> 0.047427461 | Q7: =+N7*H7/10^6 -> 2.3267355 | R7: =O7*H7 -> 191.27954 | S7: کوهستان وچهل بوستان | U7: =L7*10*31/O$3 -> 1130.9742 | W7: =J7+15/100*(1-J7) -> 0.26435381 | X7: یال 1 اراضی قهوه خانه و کوهسنگی | Y7: 12 | Z7: 190 | AA7: =+Y7/Z7 -> 0.063157895
B8: * | C8: =ک.ج2!V25 -> 134.3125 | D8: =ک.ج2!S25 -> توسعه 98 با افزایش25% (حاشیه کمربند جنوبی) | H8: =ک.ج2!V25 -> 134.3125 | I8: =ک.ج2!R25 -> 13.56962 | J8: =N$3/I8 -> 0.36847015 | K8: =IF(W$5=1,(J8)^0.5,J8+15/100*(1-J8)) -> 0.46319963 | L8: =I$3*K8/L$3/(1-M$3)*$J$3*$K$3 -> 1.4063594 | M8: =+L8*I8 -> 19.083763 | N8: =ROUND(U8,-1) -> 1980 | O8: =L8/8.64*24/P$3 -> 0.16277308 | P8: =U8/((6*31+3*30)*24*3600)*1000 -> 0.083102197 | Q8: =+N8*H8/10^6 -> 0.26593875 | R8: =O8*H8 -> 21.862459 | S8: کوهستان وچهل بوستان | U8: =L8*10*31/O$3 -> 1981.6882 | W8: =J8+15/100*(1-J8) -> 0.46319963 | X8: یال 2 اراضی قهوه خانه و کوهسنگی | Y8: 9 | Z8: 140 | AA8: =+Y8/Z8 -> 0.064285714
B9: * | C9: =ک.ج2!V26 -> 10 | D9: =ک.ج2!S26 -> توسعه 98 (استعلام انتهای لادن) | H9: =ک.ج2!V26-C9 -> 0 | I9: =ک.ج2!R26 -> 27.855153 | J9: =N$3/I9 -> 0.1795 | K9: =IF(W$5=1,(J9)^0.5,J9+15/100*(1-J9)) -> 0.302575 | L9: =I$3*K9/L$3/(1-M$3)*$J$3*$K$3 -> 0.91867344 | M9: =+L9*I9 -> 25.589789 | N9: =ROUND(U9,-1) -> 1290 | O9: =L9/8.64*24/P$3 -> 0.10632794 | P9: =U9/((6*31+3*30)*24*3600)*1000 -> 0.054284688 | Q9: =+N9*H9/10^6 -> 0 | R9: =O9*H9 -> 0 | S9: کوهستان وچهل بوستان | U9: =L9*10*31/O$3 -> 1294.4944 | W9: =J9+15/100*(1-J9) -> 0.302575 | X9: یال 3 اراضی قهوه خانه و کوهسنگی | Y9: 16 | Z9: 245 | AA9: =+Y9/Z9 -> 0.065306122
C10: =ک.ج2!V27 -> 250 | D10: =ک.ج2!S27 -> اراضی منابع طبیعی-ملی | H10: =ک.ج2!V27 -> 250 | I10: =ک.ج2!R27 -> 30.769231 | J10: =N$3/I10 -> 0.1625 | K10: =IF(W$5=1,(J10)^0.5,J10+15/100*(1-J10)) -> 0.288125 | L10: =I$3*K10/L$3/(1-M$3)*$J$3*$K$3 -> 0.87480058 | M10: =+L10*I10 -> 26.916941 | N10: =ROUND(U10,-1) -> 1230 | O10: =L10/8.64*24/P$3 -> 0.10125007 | P10: =U10/((6*31+3*30)*24*3600)*1000 -> 0.051692228 | Q10: =+N10*H10/10^6 -> 0.3075 | R10: =O10*H10 -> 25.312517 | S10: کوهستان وچهل بوستان | U10: =L10*10*31/O$3 -> 1232.6735 | W10: =J10+15/100*(1-J10) -> 0.288125 | X10: یال 4 اراضی قهوه خانه و کوهسنگی | Y10: 30 | Z10: 440 | AA10: =+Y10/Z10 -> 0.068181818
C11: =ک.ج2!V28 -> 250.0375 | D11: =ک.ج2!S28 -> اراضی قهوه خانه وکوهسنگی | H11: =ک.ج2!V28 -> 250.0375 | I11: =ک.ج2!R28 -> 30.769231 | J11: =N$3/I11 -> 0.1625 | K11: =IF(W$5=1,(J11)^0.5,J11+15/100*(1-J11)) -> 0.288125 | L11: =I$3*K11/L$3/(1-M$3)*$J$3*$K$3 -> 0.87480058 | M11: =+L11*I11 -> 26.916941 | N11: =ROUND(U11,-1) -> 1230 | O11: =L11/8.64*24/P$3 -> 0.10125007 | P11: =U11/((6*31+3*30)*24*3600)*1000 -> 0.051692228 | Q11: =+N11*H11/10^6 -> 0.30754613 | R11: =O11*H11 -> 25.316314 | S11: کوهستان وچهل بوستان | U11: =L11*10*31/O$3 -> 1232.6735 | W11: =J11+15/100*(1-J11) -> 0.288125 | X11: یال 5 اراضی قهوه خانه و کوهسنگی | Y11: 7 | Z11: 100 | AA11: =+Y11/Z11 -> 0.07
B12: خطا | C12: =ک.ج2!V29 -> 189 | D12: =ک.ج2!S29 -> اراضی آبشر | H12: =ک.ج2!V29-H13 -> 101.75 | I12: =ک.ج2!R29 -> 22.235294 | J12: =N$3/I12 -> 0.22486772 | K12: =IF(W$5=1,(J12)^0.5,J12+15/100*(1-J12)) -> 0.34113757 | L12: =I$3*K12/L$3/(1-M$3)*$J$3*$K$3 -> 1.0357565 | M12: =+L12*I12 -> 23.03035 | N12: =ROUND(U12,-1) -> 1460 | O12: =L12/8.64*24/P$3 -> 0.11987922 | P12: =U12/((6*31+3*30)*24*3600)*1000 -> 0.061203161 | Q12: =+N12*H12/10^6 -> 0.148555 | R12: =O12*H12 -> 12.197711 | S12: کوهستان وچهل بوستان | U12: =L12*10*31/O$3 -> 1459.4751 | W12: =J12+15/100*(1-J12) -> 0.34113757 | X12: اراضی زکریا | Y12: 31 | Z12: 490 | AA12: =+Y12/Z12 -> 0.063265306
C13: =ک.ج2!V30 -> 87.25 | D13: =ک.ج2!S30 -> توسعه 98 (تکمیل آبشر) | H13: =ک.ج2!V30 -> 87.25 | I13: =ک.ج2!R30 -> 22.65625 | J13: =N$3/I13 -> 0.22068966 | K13: =IF(W$5=1,(J13)^0.5,J13+15/100*(1-J13)) -> 0.33758621 | L13: =I$3*K13/L$3/(1-M$3)*$J$3*$K$3 -> 1.0249739 | M13: =+L13*I13 -> 23.222065 | N13: =ROUND(U13,-1) -> 1440 | O13: =L13/8.64*24/P$3 -> 0.11863124 | P13: =U13/((6*31+3*30)*24*3600)*1000 -> 0.060566015 | Q13: =+N13*H13/10^6 -> 0.12564 | R13: =O13*H13 -> 10.350576 | S13: کوهستان وچهل بوستان | U13: =L13*10*31/O$3 -> 1444.2814 | W13: =J13+15/100*(1-J13) -> 0.33758621 | X13: عرصه لادن تا دلاوران | Y13: 74 | Z13: 1100 | AA13: =+Y13/Z13 -> 0.067272727
B14: * | C14: =ک.ج2!V31 -> 34 | D14: =ک.ج2!S31 -> توسعه 98 با ابلاغ افزایش25% (حاشیه بلوار نماز) | H14: =ک.ج2!V31-C14 -> 0 | I14: =ک.ج2!R31 -> 22.666667 | J14: =N$3/I14 -> 0.22058824 | K14: =IF(W$5=1,(J14)^0.5,J14+15/100*(1-J14)) -> 0.3375 | L14: =I$3*K14/L$3/(1-M$3)*$J$3*$K$3 -> 1.0247122 | M14: =+L14*I14 -> 23.226809 | N14: =ROUND(U14,-1) -> 1440 | O14: =L14/8.64*24/P$3 -> 0.11860095 | P14: =U14/((6*31+3*30)*24*3600)*1000 -> 0.060550549 | Q14: =+N14*H14/10^6 -> 0 | R14: =O14*H14 -> 0 | S14: کوهستان وچهل بوستان | U14: =L14*10*31/O$3 -> 1443.9126 | W14: =J14+15/100*(1-J14) -> 0.3375 | X14: باقیمانده کل عرصه | Y14: 68 | Z14: 1000 | AA14: =+Y14/Z14 -> 0.068
C15: =ک.ج2!V32 -> 187.5 | D15: =ک.ج2!S32 -> اراضی مینوش ومغان با افزایش 25% | H15: =ک.ج2!V32 -> 187.5 | I15: =ک.ج2!R32 -> 19.646365 | J15: =N$3/I15 -> 0.2545 | K15: =IF(W$5=1,(J15)^0.5,J15+15/100*(1-J15)) -> 0.366325 | L15: =I$3*K15/L$3/(1-M$3)*$J$3*$K$3 -> 1.1122302 | M15: =+L15*I15 -> 21.851281 | N15: =ROUND(U15,-1) -> 1570 | O15: =L15/8.64*24/P$3 -> 0.12873035 | P15: =U15/((6*31+3*30)*24*3600)*1000 -> 0.065722014 | Q15: =+N15*H15/10^6 -> 0.294375 | R15: =O15*H15 -> 24.13694 | S15: کوهستان وچهل بوستان | U15: =L15*10*31/O$3 -> 1567.2334 | W15: =J15+15/100*(1-J15) -> 0.366325
C16: =ک.ج2!V33 -> 100 | D16: =ک.ج2!S33 -> اراضی مینوش ومغان(ترک تشریفات) | H16: =ک.ج2!V33 -> 100 | I16: =ک.ج2!R33 -> 17.241379 | J16: =N$3/I16 -> 0.29 | K16: =IF(W$5=1,(J16)^0.5,J16+15/100*(1-J16)) -> 0.3965 | L16: =I$3*K16/L$3/(1-M$3)*$J$3*$K$3 -> 1.203847 | M16: =+L16*I16 -> 20.755983 | N16: =ROUND(U16,-1) -> 1700 | O16: =L16/8.64*24/P$3 -> 0.13933415 | P16: =U16/((6*31+3*30)*24*3600)*1000 -> 0.071135682 | Q16: =+N16*H16/10^6 -> 0.17 | R16: =O16*H16 -> 13.933415 | S16: کوهستان وچهل بوستان | U16: =L16*10*31/O$3 -> 1696.3299 | W16: =J16+15/100*(1-J16) -> 0.3965
C17: =ک.ج2!V34 -> 205 | D17: =ک.ج2!S34 -> بزرگراه آسیایی بعد از نیروگاه توس | H17: =ک.ج2!V34 -> 205 | I17: =ک.ج2!R34 -> 35.964912 | J17: =N$3/I17 -> 0.13902439 | K17: =IF(W$5=1,(J17)^0.5,J17+15/100*(1-J17)) -> 0.26817073 | L17: =I$3*K17/L$3/(1-M$3)*$J$3*$K$3 -> 0.81421574 | M17: =+L17*I17 -> 29.283198 | N17: =ROUND(U17,-1) -> 1150 | O17: =L17/8.64*24/P$3 -> 0.094237933 | P17: =U17/((6*31+3*30)*24*3600)*1000 -> 0.048112252 | Q17: =+N17*H17/10^6 -> 0.23575 | R17: =O17*H17 -> 19.318776 | S17: سوران و و یرانی | U17: =L17*10*31/O$3 -> 1147.304 | W17: =J17+15/100*(1-J17) -> 0.26817073
C18: =ک.ج2!V35 -> 85 | D18: =ک.ج2!S35 -> حدفاصل مسیر رفت‌وبرگشت جاده بهشت رضا(ع) | H18: =ک.ج2!V35 -> 85 | I18: =ک.ج2!R35 -> 16.966068 | J18: =N$3/I18 -> 0.29470588 | K18: =IF(W$5=1,(J18)^0.5,J18+15/100*(1-J18)) -> 0.4005 | L18: =I$3*K18/L$3/(1-M$3)*$J$3*$K$3 -> 1.2159918 | M18: =+L18*I18 -> 20.630599 | N18: =ROUND(U18,-1) -> 1710 | O18: =L18/8.64*24/P$3 -> 0.14073979 | P18: =U18/((6*31+3*30)*24*3600)*1000 -> 0.071853318 | Q18: =+N18*H18/10^6 -> 0.14535 | R18: =O18*H18 -> 11.962882 | S18: جزایر میانی بهشت رضا(ع) | U18: =L18*10*31/O$3 -> 1713.443 | W18: =J18+15/100*(1-J18) -> 0.4005
C19: =ک.ج2!V36 -> 8.6580087 | D19: =ک.ج2!S36 -> توسعه سال 98جاده بهشت رضا (ع) | H19: =ک.ج2!V36 -> 8.6580087 | I19: =ک.ج2!R36 -> 21.645022 | J19: =N$3/I19 -> 0.231 | K19: =IF(W$5=1,(J19)^0.5,J19+15/100*(1-J19)) -> 0.34635 | L19: =I$3*K19/L$3/(1-M$3)*$J$3*$K$3 -> 1.0515824 | M19: =+L19*I19 -> 22.761524 | N19: =ROUND(U19,-1) -> 1480 | O19: =L19/8.64*24/P$3 -> 0.12171093 | P19: =U19/((6*31+3*30)*24*3600)*1000 -> 0.062138319 | Q19: =+N19*H19/10^6 -> 0.012813853 | R19: =O19*H19 -> 1.0537743 | S19: جزایر میانی بهشت رضا(ع) | U19: =L19*10*31/O$3 -> 1481.7752 | W19: =J19+15/100*(1-J19) -> 0.34635
B20: =C20-H20 -> 152.25 | C20: =SUM(C7:C19) -> 3620.816 | E20: جمع کمربند جنوبی | H20: =SUM(H7:H19) -> 3468.566 | I20: =SUMPRODUCT(I7:I19,H7:H19)/SUM(H7:H19) -> 32.400513 | J20: =N$3/I20 -> 0.15431855 | K20: =IF(W$5=1,(J20)^0.5,J20+15/100*(1-J20)) -> 0.28117076 | L20: =I$3*K20/L$3/(1-M$3)*$J$3*$K$3 -> 0.85368623 | M20: =+L20*I20 -> 27.659872 | N20: =ROUND(U20,-1) -> 1200 | O20: =L20/8.64*24/P$3 -> 0.098806277 | P20: =U20/((6*31+3*30)*24*3600)*1000 -> 0.050444575 | Q20: =+N20*H20/10^6 -> 4.1622792 | R20: =O20*H20 -> 342.71609 | U20: =L20*10*31/O$3 -> 1202.9215 | X20: کل عرصه | Y20: 250 | Z20: 3705 | AA20: =+Y20/Z20 -> 0.067476383
E21: کمربند شمالی | H21: 181 | I21: - | J21: - | K21: - | L21: =L20 -> 0.85368623 | M21: =M20 -> 27.659872 | N21: =ROUND(U21,-1) -> 1200 | O21: =L21/8.64*24/P$3 -> 0.098806277 | P21: =U21/((6*31+3*30)*24*3600)*1000 -> 0.050444575 | Q21: =+N21*H21/10^6 -> 0.2172 | R21: =O21*H21 -> 17.883936 | U21: =L21*10*31/O$3 -> 1202.9215
E22: مجموع کمربند سبز شهر مشهد | H22: =SUM(H20:H21) -> 3649.566 | Q22: =SUM(Q20:Q21) -> 4.3794792 | R22: =SUM(R20:R21) -> 360.60003
E24: مقدار توسعه تا سال 1400 | H24: =7395000/10000 -> 739.5 | I24: =I20 -> 32.400513 | J24: =I$59/I24 -> 0.15431855 | K24: =(J24)^0.5 -> 0.39283399 | L24: =H$59*K24/L$3/(1-M$3) -> 1.1921745 | M24: =+L24*I24 -> 38.627064 | N24: =ROUND(U24,-1) -> 1680 | O24: =L24/8.64*24/P$3 -> 0.13798316 | P24: =U24/((6*31+3*30)*24*3600)*1000 -> 0.070445946 | Q24: =+N24*H24/10^6 -> 1.24236 | R24: =O24*H24 -> 102.03854 | U24: =L24*10*31/O$3 -> 1679.8822
E25: مقدار مفروض توسعه سالانه | H25: =ROUND((1425-1424)*240000/2*I25/10000,-1) -> 390 | I25: =I24 -> 32.400513 | J25: =I$59/I25 -> 0.15431855 | K25: =(J25)^0.5 -> 0.39283399 | L25: =H$59*K25/L$3/(1-M$3) -> 1.1921745 | M25: =+L25*I25 -> 38.627064 | N25: =ROUND(U25,-1) -> 1680 | O25: =L25/8.64*24/P$3 -> 0.13798316 | P25: =U25/((6*31+3*30)*24*3600)*1000 -> 0.070445946 | Q25: =+N25*H25/10^6 -> 0.6552 | R25: =O25*H25 -> 53.813431 | U25: =L25*10*31/O$3 -> 1679.8822
E26: مقدار مفروض تا سال 1425 | H26: =ROUND((1425-1400)*250000/2*I26/10000,-3) -> 10000 | I26: =I25 -> 32.400513 | J26: =I$59/I26 -> 0.15431855 | K26: =(J26)^0.5 -> 0.39283399 | L26: =H$59*K26/L$3/(1-M$3) -> 1.1921745 | M26: =+L26*I26 -> 38.627064 | N26: =ROUND(U26,-1) -> 1680 | O26: =L26/8.64*24/P$3 -> 0.13798316 | P26: =U26/((6*31+3*30)*24*3600)*1000 -> 0.070445946 | Q26: =+N26*H26/10^6 -> 16.8 | R26: =O26*H26 -> 1379.8316 | U26: =L26*10*31/O$3 -> 1679.8822
E27: طرح مجموعه شهری | H27: 19000 | I27: =I26 -> 32.400513 | J27: =I$59/I27 -> 0.15431855 | K27: =(J27)^0.5 -> 0.39283399 | L27: =H$59*K27/L$3/(1-M$3) -> 1.1921745 | M27: =+L27*I27 -> 38.627064 | N27: =ROUND(U27,-1) -> 1680 | O27: =L27/8.64*24/P$3 -> 0.13798316 | P27: =U27/((6*31+3*30)*24*3600)*1000 -> 0.070445946 | Q27: =+N27*H27/10^6 -> 31.92 | R27: =O27*H27 -> 2621.68 | U27: =L27*10*31/O$3 -> 1679.8822
H29: =25*30 -> 750 | P29: =T65/((6*31+3*30)*P$3*3600)*1000 -> 0.14697702
E30: مجموع در سال 1398 | H30: =H20+H24/2 -> 3838.316 | I30: =I20 -> 32.400513 | J30: =I$59/I30 -> 0.15431855 | K30: =(J30)^0.5 -> 0.39283399 | L30: =H$59*K30/L$3/(1-M$3) -> 1.1921745 | M30: =+L30*I30 -> 38.627064 | N30: =ROUND(U30,-1) -> 1680 | O30: =L30/8.64*24/P$3 -> 0.13798316 | P30: =U30/((6*31+3*30)*24*3600)*1000 -> 0.070445946 | Q30: =+N30*H30/10^6 -> 6.4483709 | R30: =O30*H30 -> 529.62296 | U30: =L30*10*31/O$3 -> 1679.8822
D32: ETc | E32: Ksp | F32: Kd | G32: Ksh | H32: Kmc | I32: IR; mm/d | J32: Kage | K32: Kstress | L32: Eff | M32: Lf | N32: Atree | O32: سهم ماه اوج | P32: ساعات کار | Q32: Ao | R32: lit/d | S32: m3/ha | T32: QHM
D33: 7.1 | E33: 0.6 | F33: 0.6 | G33: =(N33/Q33)^0.5 -> 0.57735027 | H33: 1 | I33: =D33*E33*F33*H33 -> 2.556 | J33: 1 | K33: 1 | L33: 0.8 | M33: 0.05 | N33: 10 | O33: 0.22 | P33: 24 | Q33: 30 | R33: =+I33*Q33*G33/L33/(1-M33)*$J33*$K33 -> 58.251603 | S33: =R33/Q33*10*31/O33 -> 2736.0602 | T33: =R33/Q33/8.64*24/P33 -> 0.22473612
E35: گونه | H35: تراکم | K35: خرداقلیم
E36: دسته | F36: وضعیت | G36: ضریب | H36: دسته | I36: وضعیت | J36: ضریب | K36: دسته | L36: تأثیر بر | M36: ضریب
F37: نیاز رطوبتی | G37: گونه | I37: سطح برگ | J37: تراکم | L37: تبخیرتعرّق | M37: خُرداقلیم
F38: خیلی کم‌نیاز | G38: 0.05 | I38: تُنُک/ کم‌تراکم | J38: 0.5 | L38: کاهنده | M38: 0.5
G39: 0.08 | J39: 0.6 | M39: 0.6
G40: 0.1 | J40: 0.7 | M40: 0.7
F41: کم‌نیاز | G41: 0.2 | J41: 0.8 | M41: 0.8
G42: 0.3 | J42: 0.9 | M42: 0.9
G43: 0.4 | I43: مبنا | J43: 1 | L43: مبنا | M43: 1
F44: متوسط‌نیاز | G44: 0.5 | I44: پُرپشت/ متراکم | J44: 1.1 | M44: 1.1
G45: 0.6 | J45: 1.2 | L45: افزاینده | M45: 1.2
...

Sheet Analysis
C2: اطلاعات اعلامی از مسئولین کمربند سبز جنوبی | K2: استخراج اطلاعات از لایه‌های نقشه ماهواره‌ای | Q2: سطح مشروب هر مخزن- گزارش ناظر | T2: سطح مشروب هر مخزن | W2: مخازن
B3: ردیف | C3: پارک جنگلی | D3: کمربند سبز | E3: نام و نشانی | F3: جمع کل | G3: سطح بانک | H3: اختلاف دو سطح | I3: سطح نقشه | J3: fid | K3: wkt_geom | L3: نام اولیه در نقشه | M3: توضیحات | N3: Area_m2 | O3: Code | Q3: =L49 -> نام مخزن | R3: مساحت؛ هکتار | V3: مساحت؛ هکتار
K4: شمال جاده کمربندی
G5: =F5/10000 -> 0 | I5: =N5/10000 -> 24.505059 | J5: 19 | K5: Polygon ((59.4748418020744225 36.29684762670549247, 59.47464937819999165 36.29659561003934698, 59.47435728384880349 36.2965053029916831, 59.47424092004749241 36.2963227207550716, 59.47391481934614887 36.2962318004030422, 59.47310027153795176 36.2963533556744693, 59.47331401359914338 36.29584103695840724, 59.47353546186982243 36.2953629432889926, 59.47390577602711659 36.29489387549808299, 59.47412322225744674 36.29463040934845708, 59.47436103630300863 36.2942775922481573, 59.47509576670112352 36.29362430194716893, 59.47593911574516312 36.29335914468730806, 59.47637940064112172 36.29313099924854669, 59.47670715768320093 36.2930237020398323, 59.47695719820482907 36.29278327736751208, 59.4774349929807471 36.29280995685582667, 59.47779273904929909 36.29271587064860682, 59.47799035323205885 36.29249570968173799, 59.47840219220312719 36.29243165541699767, 59.47889807743683832 36.29217846715935281, 59.47958029484961173 36.29195444532859938, 59.48018209813797341 36.29180393362005219, 59.48075147421293707 36.29156402371358325, 59.48155752723639722 36.29125603951599288, 59.48209303016187732 36.29116653830575245, 59.48245983643975876 36.2910957230902369, 59.48312483721910127 36.29075181548054729, 59.48372205894534659 36.29053734725619762, 59.48520008777680346 36.29006728303122742, 59.48582254704780325 36.28974882212563102, 59.48674442051952127 36.28954034569800058, 59.48743692752056944 36.28925457349715344, 59.48783509867914887 36.28949408442816349, 59.48812460033280303 36.28967578953650985, 59.48821531151517661 36.28996758266404044, 59.48854525711100649 36.29035736192089701, 59.48856741012166083 36.29036535985453327, 59.4886973844399165 36.29062398984409299, 59.48788496204777232 36.29089410086255185, 59.48726697090160798 36.29095088465638241, 59.48619509848177245 36.29123260528363204, 59.485223125961042 36.29151592022463291, 59.48461193741467667 36.29172212916215301, 59.48372545134908762 36.29188979304238671, 59.48311417558201697 36.29211555190987326, 59.48308423722902916 36.29213220750479252, 59.48238907958174337 36.29219768087458675, 59.48167991337181348 36.2925243698850224, 59.48051214502361717 36.29277679949291269, 59.47963413695214285 36.29301625362631256, 59.47983280811787665 36.2931974868825975, 59.48025853043090194 36.2933942138519825, 59.48091784555312245 36.29334990390623261, 59.48086649281376026 36.29355375031992281, 59.48057928981567244 36.29371982708568822, 59.47985622304086206 36.29384519120434049, 59.4794039960698484 36.29396858973890261, 59.47894082981282082 36.2941634937540627, 59.47863379107879211 36.29394104147173294, 59.47815015137838657 36.29405710353987047, 59.47756336451011805 36.29437401626943682, 59.47720163317924857 36.29467352544831016, 59.47671370023478232 36.29473500154777099, 59.4766771801556402 36.29475365934828091, 59.47667272152597917 36.29476301395560967, 59.47654114450241991 36.29503791832951975, 59.47632289565636654 36.29522835177032647, 59.47608669846324148 36.29551767194725898, 59.47571599866947878 36.29582132874124056, 59.47536211965520891 36.29597291023001304, 59.4748418020744225 36.29684762670549247)) | M5: افزایش تراکم خورشید2 - شمالی | N5: 245050.59 | P5: =K50 -> 1 | Q5: =L50 -> مخزن 3 | R5: =M50 -> 221 | T5: 1 | U5: زیر دست مخزن 1 | V5: 221 | W5: 5 | X5: مخزن 2- کوهستان- 500م.م. | AA5: 4 | AB5: مخزن 1- لادن- 500م.م.
G6: =F6/10000 -> 0 | I6: =N6/10000 -> 10.16633 | J6: 18 | K6: Polygon ((59.47200494084314215 36.30202474628288911, 59.47129595638416077 36.30233590646618325, 59.47096499211731668 36.30209871019287959, 59.47076572449074661 36.30168202415782019, 59.47059745759892735 36.30152415949690692, 59.47062366181987869 36.30115148042379758, 59.47020896994786199 36.30164807020214113, 59.46963884282610735 36.3018309816062299, 59.46934173259810308 36.3021716483351824, 59.46911674722637287 36.30243580075701715, 59.46872578065285353 36.30260068806499163, 59.4685221433701372 36.30233290601420038, 59.46836393856324321 36.30193636286332293, 59.46848577678502323 36.30169512929561648, 59.4688389932297099 36.30137713038038783, 59.46919001948729289 36.30118835528306676, 59.46948955660622005 36.30124314149116316, 59.46986360524161341 36.30122547391807331, 59.47006453565673212 36.30127581436909168, 59.47034593765567223 36.30123057806652298, 59.47078507255636737 36.30080898894868113, 59.47077652210511189 36.30039324939672696, 59.47069928610891054 36.29986009248074197, 59.47123282256554688 36.29933444547454968, 59.47162355962986879 36.29874803319974319, 59.47185548144970113 36.29839893614794022, 59.47211305403718029 36.29797011983558974, 59.47176232903643722 36.29770222497059962, 59.47247160584100101 36.29696174678060316, 59.47310757481125165 36.29635239507418731, 59.47391275390547349 36.29619608719910673, 59.47425332606859882 36.29630712619812272, 59.47441944310600803 36.2964871841305623, 59.47468096612446686 36.29660419041937303, 59.47477268535193673 36.29677433664900121, 59.4747716876248802 36.29691582490234225, 59.47477474474420234 36.29712610895457203, 59.47471116860847928 36.29738204307088978, 59.47471320377943016 36.29741453085188141, 59.47454709303306686 36.29752839794247166, 59.47442970987074773 36.29760450209023048, 59.47423854101931795 36.29771561239645195, 59.4740977376548301 36.29785989592379281, 59.47389036444415211 36.29803139924865718, 59.47382093104371847 36.2981718544101426, 59.47386717724631211 36.29835990994450867, 59.47373125326667065 36.29842031051131812, 59.47387692871865283 36.29850321934146251, 59.47386423830592861 36.29856973141504284, 59.47368882324769146 36.29856887930156262, 59.47340226700146104 36.29848873427332023, 59.47319069762190225 36.29867048212759073, 59.47287851699289973 36.29888051931620652, 59.47250913328002042 36.29913237193928666, 59.47223451476678946 36.29929931911934204, 59.47222133560958213 36.29949248013377172, 59.4720321332707087 36.29968476057923965, 59.47177885535447217 36.29983030915310849, 59.47147658861892694 36.30021559336245218, 59.47169366658970802 36.30062696235639663, 59.47170748091028258 36.30063143483579324, 59.47163780401751865 36.30128051153325686, 59.47170228352614885 36.30165323995816351, 59.47190373782338213 36.30180661750424065, 59.47209106505749787 36.30193972012337156, 59.47200494084314215 36.30202474628288911)) | M6: افزایش تراکم خورشید - شمالی | N6: 101663.3 | W6: 6 | X6: مخزن 3- . . . - 1000م.م.
G7: =F7/10000 -> 0 | I7: =N7/10000 -> 22.544036 | J7: 17 | K7: Polygon ((59.50326114211385686 36.28528803939143188, 59.5027319236329717 36.285998634337993, 59.50174452046898921 36.28737188943237868, 59.50112865485964164 36.28817187917292841, 59.50047785881407236 36.28769459814583342, 59.4998296333109522 36.28743123596194664, 59.49962113262188268 36.2870594492536469, 59.49927583343090021 36.28673011723107322, 59.49888091916660926 36.28643020985891354, 59.49845778445703814 36.28629092534905709, 59.49821091712875898 36.28594026340311984, 59.49756557153771297 36.28612529382704821, 59.4970429372166123 36.2855971946951712, 59.4964449981385215 36.28506767109627162, 59.49560403772269268 36.28440136312867992, 59.49716778760016211 36.28341272101341275, 59.49856799651421824 36.28255697188450313, 59.49888244932292736 36.28244826230695708, 59.49915313958963026 36.28206933648404231, 59.4993201782624439 36.28239143754245788, 59.49948552811940061 36.28254133955176286, 59.49958465133040875 36.28284319881297648, 59.49977188406231932 36.28299412800578949, 59.50000317155468821 36.28327157061352182, 59.50119265008680713 36.28322496032434685, 59.50199981434784746 36.28376426075279682, 59.50197726620628202 36.28412296948901172, 59.50326114211385686 36.28528803939143188)) | M7: بین سرافرازان و دلاوران - شمالی | N7: 225440.36 | P7: =K51 -> 2 | Q7: =L51 -> مخزن شاهین | R7: =M51 -> 177 | T7: 2 | U7: زیر دست مخزن 2 | V7: 444.37 | W7: 7 | X7: مخزن 4- . . . - 1000م.م.
B8: =B57 -> 8 | C8: =D57 -> کوهستان وچهل بوستان | D8: =C57 -> 0 | E8: =E57 -> توسعه 98 با ابلاغ افزایش25% (حاشیه بلوار نماز) | F8: =F57 -> 340000 | G8: =F8/10000 -> 34 | H8: =I8-G8 -> -0.82617283 | I8: =N8/10000 -> 33.173827 | J8: 23 | K8: Polygon ((59.52719089737190217 36.28946035465901332, 59.52648530550457906 36.28978719661689212, 59.52598892408391151 36.28994880599722705, 59.52430943420492326 36.290087458094753, 59.52322611371732819 36.29003167677125674, 59.52220118381102054 36.29013268449561735, 59.52150091927298803 36.28970545484393284, 59.52035956060208832 36.28880228957039122, 59.51955802956708652 36.28780156406040192, 59.51929472960730294 36.28706247595187051, 59.51901923941505146 36.28613461228417947, 59.51826917074067325 36.28472634404627684, 59.51871625799053334 36.28346033611688171, 59.51815314856523287 36.28298377996819113, 59.51743960235440056 36.28281038956129123, 59.51696126901134676 36.28256058618647728, 59.5164245877185607 36.2823578178970223, 59.51624083063271087 36.28199860362394702, 59.51723996575628917 36.28148660664994196, 59.51821137294125919 36.28146583339805176, 59.51885502791669325 36.28217659534465156, 59.51887415090082811 36.28220683641430355, 59.5191205657224387 36.28273582282049148, 59.51955947357335219 36.28286935966144, 59.51975673455449112 36.28335354485398057, 59.52032791032063841 36.28356324291789292, 59.52101481354330303 36.28394565255877779, 59.52141313688977675 36.28491085784712311, 59.52166156240630102 36.28544333901260188, 59.52268077328049856 36.28623048529860284, 59.5234655450650223 36.28664051553567305, 59.52500551363183234 36.28678440467798794, 59.52719089737190217 36.28946035465901332)) | L8: توسعه 98 با افزایش25% (حاشیه کمربند جنوبی) | M8: کشت جدید-حاشیه نماز - شمالی | N8: 331738.27 | O8: 8 | Q8: Polygon ((59.51993012327333332 36.27160452790071332, 59.51804500828796307 36.26973873289929173, 59.51704652569082299 36.26906266044463223, 59.5169912381533095 36.26902036003326657, 59.51546703433930929 36.26857121204110967, 59.51533291991960084 36.26847449346818308, 59.51424669391138167 36.26679994290788756, 59.51435595273777324 36.26553646797445651, 59.5129639472611629 36.26523294826389332, 59.51290967990301084 36.26524159184280194, 59.51149541821383337 36.26430934889288693, 59.5114663007802065 36.26428067845291281, 59.50783214285190326 36.26396316222503913, 59.50607506283370185 36.26335268876402296, 59.50600174866782055 36.26334800741275188, 59.50347685363617245 36.26254831110112065, 59.50331673854717707 36.26243469480777293, 59.50306424813049233 36.26087307642477242, 59.50305851376757715 36.26079890780732029, 59.503830323720031 36.25809597536172646, 59.50377525046238247 36.25663573331866729, 59.50345043187258653 36.25501575868953807, 59.50320159619172955 36.25441923748795148, 59.50352352908110731 36.25301611388336909, 59.5024542365164919 36.25119242436002054, 59.5035593399720284 36.25049654417769318, 59.50410407645446753 36.2497519937003716, 59.50443925177616933 36.24947407204747662, 59.50598212532317177 36.24967739615347284, 59.50662287771429249 36.24971081006305695, 59.50722857056179294 36.24946572611654716, 59.5081597156367792 36.24959367877138305, 59.50814554200105277 36.24839732070945075, 59.50936895009652261 36.24800737230741277, 59.5098447631868126 36.24833364387944101, 59.5099785502884373 36.24814630501712287, 59.51094854852040328 36.24785510500991847, 59.51131234790855729 36.24841516368798722, 59.51170860744438329 36.24863084647682854, 59.51197137591903896 36.24905071502045217, 59.51211213989004278 36.24869707131779251, 59.51210606378420209 36.24868675004549345, 59.5120938237225019 36.24866595814278725, 59.51189087949840228 36.24853370673930186, 59.51186184258283873 36.24849911671736891, 59.51197115185868824 36.24821469669085161, 59.51291205944745144 36.24788909200933773, 59.51340776450380332 36.24766829449522731, 59.51287115594414701 36.24641912168299029, 59.51226658315209761 36.24553968495361289, 59.51181060736850981 36.24545299083916206, 59.51107001820422227 36.24587935775890912, 59.51104148748721201 36.24546432126248874, 59.5110480245891722 36.24545820189612755, 59.51106772178297888 36.24543418937435746, 59.51190655786996331 36.24506377369193899, 59.51273532618184703 36.24472791818531192, 59.51282239472997304 36.24450184230043703, 59.51347907273279958 36.24452794903049835, 59.51385364088255159 36.24471225446450262, 59.51385733763847696 36.24470917366431166, 59.51462533563316271 36.24442975230073216, 59.51567080717548208 36.24445980168479764, 59.51729396546475215 36.24424250694968208, 59.51889341335478179 36.24389961782031122, 59.52060204379257868 36.24358181091368891, 59.52133872228620248 36.24250107120972331, 59.52133400841046296 36.24249349078486659, 59.52181294408210732 36.24098421215192189, 59.52445758909785667 36.23955249331139328, 59.52604066323409882 36.23914087849510679, 59.52753964399811082 36.23879752879042826, 59.52798561505056085 36.23925629841333773, 59.52798995302661922 36.23927628041376892, 59.52845619054546944 36.23953220567801736, 59.52846703558906682 36.23951449920785706, 59.52849242060501211 36.23948242488209104, 59.52850921555373276 36.23945336401971673, 59.52864846400846233 36.23829266171988905, 59.52881943226137906 36.23717135017580659, 59.53100069309194708 36.23674228242594353, 59.5297062217279418 36.24034054696574714, 59.52916939372744309 36.24038628106440285, 59.52845109444996297 36.24038861954041124, 59.52804822532468876 36.24060564210478219, 59.52743600098021659 36.24039643360355711, 59.52703888469702775 36.24051886483137963, 59.52705352991686283 36.24051825718100872, 59.52629418788802695 36.24091112897836808, 59.52556000334254804 36.24083700016049647, 59.52507416903044657 36.24115459123469662, 59.52466393565708103 36.24095062955299795, 59.52414867930131948 36.24116317532912745, 59.52368739324241176 36.24177349930864267, 59.52345762321228051 36.24208387395528064, 59.52238598490546906 36.24246191934594918, 59.5216788927462872 36.24331781850843726, 59.52172229056151309 36.24330973313465876, 59.52318953827097658 36.24285521086613926, 59.5232229381973994 36.24284867852618675, 59.52386186356098108 36.24299821915705877, 59.52350175780568264 36.24316661683970864, 59.52299601343393931 36.24373380514939669, 59.52300166539353654 36.24374337306837646, 59.52301296270690756 36.24376249721657217, 59.52313747224376783 36.24455712168875721, 59.52278472913406659 36.24567077554333849, 59.52231403455409264 36.24622177491894348, 59.52185471197161348 36.2466778888472092, 59.52138460081164339 36.24696123498554812, 59.5206899387627999 36.24690539346377705, 59.52014869743059222 36.24665443723692704, 59.51949026253532082 36.24638664914363062, 59.51901391211399073 36.24642321609408668, 59.51815671747345249 36.24541966356959222, 59.51772889979736192 36.24562776217644, 59.51733100678436017 36.24555718268300808, 59.51732932983740199 36.2455621814077773, 59.51716509545089195 36.24561548574963155, 59.51717046282656298 36.24561411577690251, 59.51692068375260902 36.24508686707122251, 59.51690205709937231 36.2448411227544085, 59.5160140952891723 36.24508598804123238, 59.51565712488370252 36.24564418803807797, 59.51537074563562157 36.24715638353421809, 59.5153887059903397 36.24720119284562969, 59.51545272613007143 36.24789467129689768, 59.515490117942079 36.24787592350595844, 59.51652643163237855 36.24703981224965332, 59.51796018472993666 36.24695038175200068, 59.51798374389967705 36.24695677023156293, 59.51878580435489141 36.24780774878647804, 59.51795551550679875 36.24823749620396995, 59.51728397101538093 36.24822399108067117, 59.51661082696013239 36.24859343496527941, 59.51623629560901207 36.24886090831356711, 59.51605872651971652 36.24916943767990318, 59.51607146636018086 36.24918295517125699, 59.5165719744198185 36.24951522888598276, 59.51692490756639131 36.24931525662678666, 59.51790151015819674 36.24982426041383832, 59.51832482791178336 36.24979604784969922, 59.5186905732776097 36.25000700859285985, 59.51994028335388975 36.24950756379767824, 59.52049006538329223 36.24955858697835254, 59.52026182680260291 36.25029508263980205, 59.51907260219635276 36.25088653830645313, 59.51781563335234182 36.251747852321202, 59.51740302395342752 36.25232444079035332, 59.51840574106527271 36.25279043747288199, 59.51816808094700662 36.25332917661560117, 59.51816032805633938 36.25333760259631788, 59.51780920638122296 36.25401224498409647, 59.51782760062297228 36.25402036866662314, 59.51895054728446866 36.25431681404827344, 59.51858910906322109 36.25502693111555175, 59.52155351573136244 36.25540784867528288, 59.51981152155477162 36.25658683563703732, 59.51986356840892256 36.2566134146126231, 59.52095349502525323 36.25770290662133277, 59.52254487607005728 36.25910950905100094, 59.522568405033077 36.25916697720391824, 59.5225838266557119 36.25920082220469709, 59.52376166703118798 36.26089527950787783, 59.52376455669364219 36.26094597068446035, 59.52477695932085311 36.26212853768628008, 59.52489448383241211 36.26479702141342898, 59.52651847051512135 36.26771808261774055, 59.52723320514613903 36.26876285261221255, 59.51993012327333332 36.27160452790071332)) | S8: زیر دست مخزن زکریا | Y8: 1 | Z8: 0 | AA8: -1 | AD8: 316.01
B9: =B52 -> 3 | C9: =D52 -> کوهستان وچهل بوستان | D9: =C52 -> 0 | E9: =E52 -> توسعه 98 (استعلام انتهای لادن) | F9: =F52 -> 100000 | G9: =F9/10000 -> 10 | H9: =I9-G9 -> 0.97159443 | I9: =N9/10000 -> 10.971594 | J9: 16 | K9: Polygon ((59.46868149596051012 36.31024506747041869, 59.46898253047798732 36.310800435530588, 59.46951716237928309 36.31128731375351748, 59.46944861315594721 36.31142854308936307, 59.46945658353222797 36.31220563863440987, 59.46945524349858658 36.31221053957884237, 59.46933374812965667 36.31215486531038295, 59.46925064113833059 36.3116015322277832, 59.46916243392445267 36.31158938293106786, 59.4687594482340387 36.31176178265646826, 59.46875956369122207 36.31201808047723034, 59.4689256623343212 36.3123166973499707, 59.4690684041000921 36.31242713298355085, 59.46929369927939746 36.31252377819996724, 59.46930512170156646 36.31253267106549742, 59.46882712870198873 36.31248511145651747, 59.46876939182939736 36.31241329682571717, 59.46844329325980283 36.31247158683633813, 59.4682775861470887 36.31217506232888326, 59.46731966398741065 36.31257133700717077, 59.46744912766070712 36.31275238911027259, 59.46742687156355345 36.31299218944086249, 59.46692184262734315 36.31328388406711127, 59.46699059258892106 36.31362601839502702, 59.46694292915206148 36.31413275190455181, 59.46659642401459678 36.31435900818647866, 59.46604120580270347 36.31436314487476125, 59.46561544506098329 36.31415184760871284, 59.46482005343533217 36.31464412360246286, 59.46492883195602275 36.31398045015434661, 59.4650567939288166 36.31324704550455351, 59.46517349118119711 36.31284921146489353, 59.46527557935831965 36.31269621446399753, 59.4659156568592735 36.31194373344325754, 59.46567014325378864 36.31176751652122903, 59.4659596181768606 36.31152236518501297, 59.4665839071103477 36.31065090352151259, 59.46726415946989164 36.3098640158655499, 59.4679351681542272 36.30972491684565284, 59.46794758206988973 36.30972701755141685, 59.46861686550973047 36.30977305915806141, 59.46863876555593009 36.30976742334855345, 59.46867147877438242 36.30975895805770648, 59.46887793935997024 36.30992584035101345, 59.46868149596051012 36.31024506747041869)) | L9: توسعه 98 (استعلام انتهای لادن) | M9: انتهای لادن- شمال جاده کمربندی | N9: 109715.94 | O9: 3 | P9: =K52 -> 3 | Q9: =L52 -> مخزن قله زو | R9: =M52 -> 267
H10: =I14-G14 -> -20.630539 | I10: =(N10+N11+N12)/10000+0 -> 20.563376 | J10: 25 | K10: Polygon ((59.50014629844194758 36.28146852903452668, 59.49989266448991287 36.28158469902187022, 59.4994660982978516 36.28177986421137291, 59.49922975756982169 36.28192856117105691, 59.50004970384740943 36.2832237721128692, 59.50100357655581718 36.28314941131098692, 59.50118641177429168 36.28257897513559271, 59.50098592268376052 36.28197822177418175, 59.500515220554 36.28148711624412215, 59.50014629844194758 36.28146852903452668)) | L10: نگهداری قدیم -زون 1 الی11 | M10: بخش شمالی کمربند- زون 7 | N10: 23078.126 | P10: =K53 -> 4 | Q10: =L53 -> مخزن 5 | R10: =M53 -> 692 | T10: 3 | U10: زیر دست مخزن 3 | V10: 692.02 | W10: 8 | X10: مخزن 5- . . . - 1000م.م.
H11: - | J11: 26 | K11: Polygon ((59.50600865283462326 36.27839575279637074, 59.50591647085072111 36.27843410772513977, 59.50544378939466128 36.2786525156487798, 59.50518439103461787 36.27884304121074877, 59.50440043154652159 36.27927985415856682, 59.50358188561041572 36.27964696102214504, 59.50305732448234153 36.27988395314360304, 59.50274028204229637 36.27991648141784253, 59.50227912940224684 36.28014882583960343, 59.50131647326610107 36.28062280631545633, 59.50094755115404865 36.28083191443391797, 59.50067662397802337 36.28107354978421739, 59.50051588830363158 36.28115625578623593, 59.50098592268376052 36.28197822177418175, 59.50118641177429168 36.28257897513559271, 59.50105501384993545 36.28298892968400224, 59.50207904208043175 36.28349506657598056, 59.50713191311722028 36.28103577658689716, 59.5049721516006116 36.28046234485218946, 59.50600865283462326 36.27839575279637074)) | L11: نگهداری قدیم -زون 1 الی11 | M11: بخش شمالی کمربند- زون 8 | N11: 147365.37 | P11: =K54 -> 5 | Q11: =L54 -> مخزن زکریا | R11: =M54 -> 383 | T11: 4 | U11: زیر دست مخزن زکریا | V11: 382.73 | W11: 9 | X11: مخزن 0- ذکریا
H12: - | J12: 27 | K12: Polygon ((59.51081514588202737 36.27666816312117248, 59.51075857357137977 36.27667288107273436, 59.51023977685131428 36.27680764652129852, 59.50962298519522875 36.27693776466468023, 59.50861421379509153 36.27690058807441886, 59.50792824924299396 36.27710970616433883, 59.50783025430698103 36.27726770612743934, 59.50755971149328616 36.27771797875296045, 59.50927422037913317 36.27885032298821244, 59.51081514588202737 36.27666816312117248)) | L12: نگهداری قدیم -زون 1 الی11 | M12: بخش شمالی کمربند- زون 8 | N12: 35190.258 | P12: =K55 -> 6 | Q12: =L55 -> مخزن 2 آبشر | R12: =M55 -> 631 | T12: 7 | U12: زیر دستمخزن 2 آبشر | V12: 630.94 | W12: 3 | X12: مخزن 2- آبشر
K13: کوهستان وچهل بوستان | P13: =K56 -> 7 | Q13: =L56 -> مخزن بتنی جدید | R13: =M56 -> 855 | T13: 6 | U13: زیر دست مخزن جدید | V13: 855.29 | W13: 11 | X13: مخزن 0- ژئوممبران
B14: =B50 -> 1 | C14: =D50 -> کوهستان وچهل بوستان | D14: =C50 -> قدیم | E14: =E50 -> نگهداری قدیم -زون 1 الی11 | F14: =F50 -> 20800580 | G14: =F14/10000 -> 2080.058 | H14: - | I14: =SUM(N14:N27)/10000 -> 2059.4275 | J14: 4 | K14: Polygon ((59.44314909399989233 36.30212582897704721, 59.44276034241961071 36.30220532425931879, 59.44216671796318963 36.30232671356125707, 59.44181498472981673 36.30389596103972849, 59.44044062271620987 36.30429240852574679, 59.44037298021075344 36.30016570962062161, 59.4402405088310033 36.30002116972259074, 59.44020319548727116 36.29994726704332919, 59.43979678589099791 36.30014420744375769, 59.4395723391526829 36.29991740398975253, 59.43952011256840962 36.29955493335646111, 59.43935747903633882 36.29929346642271071, 59.43932912277995939 36.29900958706264902, 59.4389350162465675 36.29841365414932142, 59.43945260486714233 36.29744642603969851, 59.43995282463159668 36.29683806274500313, 59.4407046346233372 36.29625885293545196, 59.44135243231301757 36.29610922069750245, 59.44155504906464671 36.29566864711495811, 59.44186884713852947 36.29540326242666026, 59.4416323032020415 36.29493365584500708, 59.44169884222471012 36.29452315550781805, 59.4419531408616777 36.2938218145943523, 59.4419634782936086 36.29336032199078943, 59.44266038978138766 36.29308052633113846, 59.44290077030645136 36.29278014594793689, 59.44261688886270179 36.2923515407062709, 59.44295981250549943 36.29200898960542077, 59.44325439757675866 36.29151767077190271, 59.44356973265521304 36.29158051122019657, 59.44428796816846727 36.29198804428376945, 59.44460687604556171 36.29145307283855004, 59.44525612480907029 36.29103641179821693, 59.4464954847058209 36.29007219553631103, 59.44700954779636248 36.28879717281409256, 59.44712255811270296 36.28807796281864739, 59.44926051237818143 36.28688188240899848, 59.45099276095118768 36.28569831894939313, 59.45177841338870195 36.28481544924896696, 59.45416086428524238 36.28586622010499241, 59.45481389114125648 36.28449036050821519, 59.45481389114125648 36.28449036050821519, 59.45568551047109196 36.28486179582233717, 59.45636583401734043 36.28525927630492731, 59.45686318496054668 36.28563395025158655, 59.45700211716147265 36.28668778482862933, 59.45774686218432237 36.28654263856685702, 59.45844187521613122 36.28561178292321188, 59.46120928733331823 36.28510001970398235, 59.46317724746879207 36.28522406913504739, 59.46541410655604665 36.2848224563198869, 59.4659382941307868 36.28695075527948433, 59.46579130712049022 36.28693508604951035, 59.46554713359560651 36.28703612986296889, 59.46486714519704009 36.28755878297349824, 59.46408365825752185 36.28780807161624011, 59.46356497496317672 36.28798166789083979, 59.46330471378723104 36.28808420960984904, 59.4629745224763866 36.28828741997511287, 59.46298860673835662 36.28834256230471311, 59.46272925253884267 36.28841264006196354, 59.46217753112536286 36.28887742432576147, 59.4613370454334671 36.28960050108847923, 59.46128778249792646 36.28975273467643348, 59.46127504038560829 36.29067952171097033, 59.46088644739054985 36.2908277978963909, 59.46091255833143663 36.29179992152717205, 59.4592841234290006 36.2928838337631916, 59.45815167891421993 36.29344770336202686, 59.45798752660896014 36.29394508472010727, 59.45762423798670682 36.29463043960036117, 59.45652976183600202 36.29496874430508058, 59.455498939456362 36.29556716526079185, 59.4551746054655581 36.29559315872781156, 59.45464566774659687 36.29515862902457712, 59.45435023777324801 36.29516722056329314, 59.45401479640558051 36.29475117673415241, 59.45405578703297778 36.29446800644522142, 59.45363394472249752 36.29430722753497207, 59.45288588535179031 36.29426945613852951, 59.45237199319286248 36.29452847275840099, 59.45169799232905206 36.29436753396630166, 59.45138537053362882 36.29467251102715153, 59.45106226789849302 36.29477464316706659, 59.45062102532242676 36.2947065706863512, 59.45012365826661949 36.2954539250907473, 59.45024126981972046 36.29607061685865688, 59.44958072479212774 36.29687735394988835, 59.44929697018739745 36.2967822224268204, 59.44897906554385258 36.29707156492065678, 59.44826466535152321 36.29707608953623321, 59.44676142001519281 36.29762927992253907, 59.44664956758442287 36.29787408218040667, 59.44583757674539015 36.29853941121926653, 59.44532901117324286 36.29969710536896343, 59.44473780543785324 36.30004738869917702, 59.44343904260931311 36.30135522723433184, 59.44314909399989233 36.30212582897704721)) | L14: نگهداری قدیم -زون 1 الی11 | M14: 10 | N14: 2012340 | O14: 1 | W14: 10 | X14: مخزن 0- بتنی
H15: - | J15: 11 | K15: Polygon ((59.50011088706383333 36.2807173935736742, 59.50036048222671781 36.28057924205360507, 59.50125108326285073 36.28013081917164584, 59.50196298765094127 36.27977765529577425, 59.50232326315099129 36.27977765529577425, 59.50283629546305519 36.27976371458367311, 59.50304381415109134 36.27972886279254539, 59.50324845063511248 36.27964754188607088, 59.50354243544315125 36.27950348750091791, 59.50383065584318132 36.27937105017034725, 59.50430045509524746 36.279147997316187, 59.5047616077353112 36.27891332643784494, 59.5050210060953475 36.27873209497968077, 59.50522276037537495 36.27860895028724997, 59.50539569261540862 36.27849742285099666, 59.50558880028341946 36.2784044831990613, 59.50581072999145249 36.27830921994099356, 59.50610935476166219 36.2781949717499117, 59.50633277580254088 36.2777495114522992, 59.50645321079220196 36.2777124012623915, 59.5068977242671906 36.27728077050897326, 59.50744158415856333 36.27763996177235128, 59.50757752104368592 36.27759125652450223, 59.50772019014171832 36.27726015466588194, 59.50777206981372558 36.27707427230518533, 59.50834274620580544 36.27684656581013201, 59.50858485134182985 36.2767675654423627, 59.50907482602190868 36.27679544793423361, 59.50981843465399379 36.27679080085294316, 59.51052745683809064 36.27660956446700169, 59.51090502556214545 36.27649338707520599, 59.51093952510075269 36.27649202524891336, 59.50872630700744281 36.27330905340180323, 59.49780741505993831 36.27012423273951924, 59.50073671450529389 36.2656832454816751, 59.50289103797482682 36.26102459983552251, 59.49986509806669233 36.25886964508332255, 59.50053721452798783 36.25865401236041663, 59.50123083670583668 36.25800348675655727, 59.50257673680651749 36.25788759758535917, 59.50403504938491039 36.25702988157453177, 59.50432334992388661 36.25745148298025811, 59.50486454779701972 36.25724600500956996, 59.50556310655885994 36.25762179738367763, 59.50597668216276759 36.25810672609397756, 59.50788501563977206 36.25872259471341152, 59.50799828980372297 36.25764046382828099, 59.50706809370794304 36.25720764507183702, 59.50685332771873703 36.2570365891636186, 59.5066330080338588 36.25677561856922893, 59.50644196715076362 36.25662438907434648, 59.50627880305952999 36.25649522683963255, 59.50595546944952474 36.25642856629814759, 59.50547846284405296 36.25633022343738077, 59.50500576365107008 36.25635333979163732, 59.50419408427895007 36.25643150171441675, 59.50148803323259727 36.25767702083005162, 59.50066728636713265 36.25696673573504114, 59.49685398591574881 36.25952245869770252, 59.49540793090095292 36.25833124204064006, 59.4931829498865099 36.25941201809391856, 59.49211034768178763 36.26081425052643681, 59.49164085693986692 36.26217236363896745, 59.49383062637266306 36.26335613042456885, 59.49344424384329244 36.26446941519982659, 59.49046207083755178 36.26627022559807045, 59.48925532867703936 36.26648339960704703, 59.48977292823344243 36.26697098483236203, 59.49100462431916725 36.2697386090772369, 59.49135113804179298 36.27022197201066689, 59.49168801669558349 36.27060301025760936, 59.49695533789203949 36.27527187557384281, 59.49805365235980759 36.27650429249072062, 59.49799148639480251 36.27775402321179143, 59.49906166496646165 36.2780462065910001, 59.49922296755202211 36.27852254244466224, 59.4988403718305392 36.27903273464166034, 59.49896075376968696 36.27981717936135198, 59.50011088706383333 36.2807173935736742)) | L15: نگهداری قدیم -زون 1 الی11 | M15: 8 | N15: 2109227.7 | O15: 1 | P15: =K57 -> 8 | Q15: =L57 -> مخزن 1 آیشر | R15: =M57 -> 316 | T15: 5 | U15: زیر دست مخزن یک آبشر | V15: 316.01 | W15: 2 | X15: مخزن 1- آبشر | AA15: 1 | AB15: مخزن 0- شهدای ارتش- 500م.م.
H16: - | J16: 10 | K16: Polygon ((59.49887705119732573 36.28140430579759368, 59.49905772601853471 36.28129253117430153, 59.49954193629061194 36.28103230918843991, 59.50011088706383333 36.2807173935736742, 59.49896075376968696 36.27981717936135198, 59.4988403718305392 36.27903273464166034, 59.49922296755202211 36.27852254244466224, 59.49906166496646165 36.2780462065910001, 59.49799148639480251 36.27775402321179143, 59.49805365235980759 36.27650429249072062, 59.49695533789203949 36.27527187557384281, 59.49168801669558349 36.27060301025760936, 59.49005909310530882 36.27146226026128062, 59.48935132426291972 36.27149449215649213, 59.48877909240790984 36.27160551922330711, 59.48823824713731057 36.27207365557261909, 59.48806669752691079 36.27269355541515239, 59.48594579148750228 36.27359398458479234, 59.48461585349784286 36.27429127511460649, 59.48408542155573997 36.27471710156208218, 59.48348861201858284 36.27537593856192188, 59.48717802983882308 36.27535491510646182, 59.48701555033382249 36.27641963528400026, 59.48698098742860907 36.27664612242306674, 59.48670131490734292 36.27726289968700257, 59.48647231950820213 36.27752710194680219, 59.48575814427321262 36.27812355960080737, 59.48553335320259094 36.27865140813752021, 59.48530411863364975 36.27913617931233148, 59.484522578366132 36.27962633904822098, 59.48319792918336191 36.28008540159085982, 59.48235769682470675 36.28012390980139656, 59.48192425912191794 36.28031378214537739, 59.4836033109318123 36.28267415293247211, 59.4844336372651199 36.28516461115645342, 59.48447243274654994 36.28682358166248179, 59.48460306326263236 36.28745835394982322, 59.48508753887975331 36.28781969122677964, 59.48564518430885073 36.28788996470626671, 59.4862548331176626 36.28821896503040989, 59.49171128535083142 36.28576371080786345, 59.49877538495434237 36.28124656232215983, 59.49887705119732573 36.28140430579759368)) | L16: نگهداری قدیم -زون 1 الی11 | M16: 7 | N16: 1745512 | O16: 1 | R16: =M58 -> 3542
H17: - | J17: 9 | K17: Polygon ((59.48028678147561266 36.29089096266121572, 59.48589346546312129 36.28875001143463663, 59.4860718712037766 36.28858889756345718, 59.4862548331176626 36.28821896503040989, 59.48564518430885073 36.28788996470626671, 59.48508753887975331 36.28781969122677964, 59.48460306326263236 36.28745835394982322, 59.48447243274654994 36.28682358166248179, 59.4844336372651199 36.28516461115645342, 59.4836033109318123 36.28267415293247211, 59.48192425912191794 36.28031378214537739, 59.48110225905423221 36.28049475330713847, 59.48067392185777891 36.28102300499580224, 59.4795047578483107 36.28154010602602852, 59.47908204469256788 36.2818287237693724, 59.47869722935789127 36.28194910257221295, 59.47819720203212768 36.28231534531183655, 59.47773479166075106 36.28290589449427728, 59.47750105991850234 36.28331529395133259, 59.47750362179934314 36.28386851793788281, 59.47760754868492228 36.28443777261281156, 59.47738589508868046 36.28481239435404859, 59.47689837463356355 36.2854032619394431, 59.47681267332352917 36.28551186167072018, 59.47727854667854785 36.28577988539030486, 59.47791241999740208 36.2865391999348077, 59.47909270093627754 36.28738790797304858, 59.47937804989361865 36.28783524591450771, 59.47905247185097721 36.28863384548387216, 59.47939169212744304 36.28914615293089696, 59.47982029853663732 36.28932534011507016, 59.47996758779262194 36.28963351649132107, 59.48016574800040246 36.28981126687099135, 59.4801792793985129 36.29024319054541792, 59.48037018761471728 36.29073143123007128, 59.48028678147561266 36.29089096266121572)) | L17: نگهداری قدیم -زون 1 الی11 | M17: 6 | N17: 536969.38 | O17: 1 | AD17: path | AE17: Makhzan | AF17: StorageName
H18: - | J18: 8 | K18: Polygon ((59.45700211716147265 36.28668778482862933, 59.45686318496054668 36.28563395025158655, 59.45636583401734043 36.28525927630492731, 59.45568551047109196 36.28486179582233717, 59.45481389114125648 36.28449036050821519, 59.45548359249894332 36.28458111998053681, 59.45588270452593349 36.2841853058109578, 59.45583771964027164 36.28339127588073865, 59.45615164182859758 36.28314514063622198, 59.4586419426691819 36.28246298813950688, 59.45895969497294686 36.28179008141975714, 59.45924632702475066 36.28147239351997655, 59.46040881557937752 36.28130683884064211, 59.46095996203929701 36.28073542185809686, 59.46180011059084336 36.28080872542712143, 59.46258960259667248 36.28104288343659789, 59.46285039415211315 36.28117772293712306, 59.46308069295473331 36.28115021181975663, 59.46324228447077331 36.28088289074322148, 59.46364453817135853 36.28067851869945315, 59.4643972646617982 36.2807221798179711, 59.46462417859495986 36.28022953194120248, 59.46558945221929093 36.2796140874024573, 59.46625278384856017 36.27966302701342016, 59.46675409738467266 36.27923447585067862, 59.46719607869186319 36.27936707917017145, 59.4679834932560567 36.27876660910253293, 59.46826869745733291 36.27828427416729795, 59.46891564821002873 36.27828620162087248, 59.46992256914099073 36.27763955420137876, 59.47031160993944354 36.27726765686131216, 59.47159613643537313 36.27632978100096039, 59.47440727113149705 36.275178574285313, 59.47583722499081915 36.27756662693681733, 59.47668551298517059 36.27724286976611978, 59.47763166204683927 36.27669306535572957, 59.47904528513919331 36.27638832021612103, 59.47977923271300682 36.27638643413975217, 59.48054438792252085 36.27707779436683211, 59.48097289972759683 36.27732552710671854, 59.48125323695462896 36.27802967823686231, 59.48150277905161687 36.27758468763384059, 59.48238516151862854 36.27732675298761222, 59.48287613190971967 36.27742596480307213, 59.48348341959273 36.27748896533279321, 59.48432134548698258 36.27853613969244151, 59.48479173610016346 36.27881340842255753, 59.48539795987115752 36.27868098374575823, 59.48553335320259094 36.27865140813752021, 59.48530411863364975 36.27913617931233148, 59.484522578366132 36.27962633904822098, 59.48319792918336191 36.28008540159085982, 59.48235769682470675 36.28012390980139656, 59.48192425912191794 36.28031378214537739, 59.48110225905423221 36.28049475330713847, 59.48067392185777891 36.28102300499580224, 59.4795047578483107 36.28154010602602852, 59.47908204469256788 36.2818287237693724, 59.47869722935789127 36.28194910257221295, 59.47819720203212768 36.28231534531183655, 59.47773479166075106 36.28290589449427728, 59.47750105991850234 36.28331529395133259, 59.47750362179934314 36.28386851793788281, 59.47760754868492228 36.28443777261281156, 59.47738589508868046 36.28481239435404859, 59.47689837463356355 36.2854032619394431, 59.47681267332352917 36.28551186167072018, 59.47591698077444988 36.28605980241218276, 59.47547157110469129 36.28618189798572757, 59.47471894364458223 36.28677426431359265, 59.47436785371176882 36.28675901704212237, 59.47423729739999487 36.28674010723108267, 59.47370964151004813 36.28663040457441724, 59.4736235456272766 36.28649183819587165, 59.47313389510271975 36.28636200781738097, 59.47273077371079353 36.28632275929447104, 59.47227297301380133 36.28635894502725279, 59.47203281630881833 36.286462071726163, 59.47174250086005287 36.28671850483735284, 59.47142171708357949 36.28687956727519293, 59.47120518156763325 36.28689571270515302, 59.4697336070860274 36.28652862185727201, 59.46903828565419303 36.28656749655762326, 59.46764189999618822 36.2870060707385278, 59.46723976149704782 36.28706428063725298, 59.4659382941307868 36.28695075527948433, 59.46541410655604665 36.2848224563198869, 59.46317724746879207 36.28522406913504739, 59.46120928733331823 36.28510001970398235, 59.45844187521613122 36.28561178292321188, 59.45774686218432237 36.28654263856685702, 59.45700211716147265 36.28668778482862933)) | L18: نگهداری قدیم -زون 1 الی11 | M18: 11 | N18: 1743722.2 | O18: 1 | Q18: wkt_geom | R18: fid | S18: Name | T18: description | U18: begin | V18: end | W18: altitudeMode | X18: tessellate | Y18: extrude | Z18: visibility | AA18: drawOrder | AB18: icon | AC18: layer | AD18: C:/Users/mohamadnejad/Desktop/New folder (2)/res5-1506m.kmz|layername=res5-1506m.kmz | AF18: مخزن 5- . . . - 1000م.م.
H19: - | J19: 12 | K19: Polygon ((59.45515590958396501 36.3091597351203319, 59.4558634737959224 36.3087649530233989, 59.45615985699053141 36.30860233045880392, 59.45685262579490882 36.30822221365811941, 59.45683854072267849 36.30785717271361079, 59.45763258512764793 36.3075030734061599, 59.45794369531662227 36.30811733927126994, 59.45814227935689189 36.30814725674130727, 59.45834296679009867 36.30812341098682339, 59.45857379747729254 36.30786672682547334, 59.4590365599675863 36.30771299363626525, 59.45944035890202173 36.3074496324375886, 59.45930096030245693 36.30715721800604001, 59.45943886134764256 36.30704360663624897, 59.45991974718764794 36.30699384051825263, 59.46007297922135137 36.306907256461038, 59.46013265184203789 36.30680347877905234, 59.46014675901661661 36.3065164957568598, 59.46037830594175944 36.30648408319851228, 59.46059160311691727 36.30655573414406945, 59.46082844724320182 36.30653137962995913, 59.46114841270082252 36.30612824735135291, 59.46134760939857955 36.30600478953360266, 59.46237238296131267 36.30566092851759663, 59.46250306021161691 36.30547232086656351, 59.46316379242207262 36.30506257328867292, 59.46337501941849268 36.30469907232256332, 59.46342399648853672 36.30440975733338149, 59.46358837805932041 36.3043024918151076, 59.46383022102274651 36.3040012143795181, 59.464401180058573 36.30370735691999329, 59.46461925490051215 36.30336288791239951, 59.46504346190319268 36.30309281890050244, 59.4651726428416012 36.30267611862314681, 59.46546925483033164 36.30236020273285646, 59.4658967846181028 36.30220441894240935, 59.46604692356653032 36.30203389754986176, 59.4664047205146602 36.30197163143147066, 59.46676477601162247 36.30159059104965991, 59.46690253929440928 36.30156235130706222, 59.46787969630830872 36.30175298334364697, 59.46790662781193504 36.30173745287243037, 59.46734927737597332 36.29918889670867799, 59.46662617400721018 36.29893457169377768, 59.46590302037537157 36.29845936534277229, 59.46599601687025682 36.29813311811035703, 59.46619176588958311 36.29787336206597814, 59.4661802701232034 36.29773047793062091, 59.46561359097452737 36.29767011750458749, 59.46509364258606212 36.29768318561635709, 59.46372261620388144 36.29716463692871287, 59.46286457885312871 36.29699635969924287, 59.46210032510597188 36.29740861810647345, 59.46039658205786083 36.29787972515944006, 59.45937360658464854 36.29760165447599718, 59.45884601556461746 36.29779479821957722, 59.4583021941609573 36.29755624494762856, 59.45822439578076768 36.29719570839257869, 59.45766539979410226 36.29677731661931972, 59.45773712975783809 36.29714367636727701, 59.45674452081750161 36.2991798006045272, 59.45615762312930741 36.30015331809376278, 59.45587334379280264 36.30031846790741668, 59.45605517990934175 36.30078132010670089, 59.45619901607509661 36.30160789207091909, 59.45638175290365268 36.30203096288855846, 59.45676462080056268 36.30211433626710971, 59.45718548071091902 36.30212181908193259, 59.45738889925949877 36.30219991145968095, 59.45753123868647094 36.30241345871370129, 59.45757213509251216 36.30268257360356188, 59.45760263254945244 36.30288325859866205, 59.45749450736383324 36.30305410580292147, 59.45663208528992527 36.30343187276088202, 59.45401637942698159 36.30438327875580029, 59.45491573746586056 36.30463725120394258, 59.45526637197219344 36.3046984947143514, 59.45549695254104705 36.30473876900006047, 59.45575368282821671 36.30565996866631195, 59.45601263347457888 36.30596809457185259, 59.45598916224439989 36.30616300847413669, 59.45587059018148324 36.30646207343335163, 59.45588283194955892 36.30663338480196245, 59.45616790604034207 36.307144789459322, 59.45596516909092344 36.30768562815509881, 59.45559561338217236 36.30792859656207128, 59.45517134146462723 36.30855022811694255, 59.45515589639715159 36.30915953944084151, 59.45515590958396501 36.3091597351203319)) | L19: نگهداری قدیم -زون 1 الی11 | M19: 2 | N19: 869788.77 | O19: 1 | Q19: PointZ (723246.84902091813273728 4017769.43398979632183909 0) | R19: 8 | S19: res5-1506m | T19: مخزن شماره 5 خط انتقال با ظرفیت 1000 متر مکعب | X19: -1 | Y19: 0 | Z19: -1 | AC19: res5-1506m res5-1506m.kmz | AD19: C:/Users/mohamadnejad/Desktop/New folder (2)/res4-1490m.kmz|layername=res4-1490m.kmz | AF19: مخزن 4- . . . - 1000م.م.
