Workbook
Name çسçر76: [3]çسçرءهآس!$C$2:$J$39
Name çسçر76: [4]çسçرءهآس!$C$2:$J$39
Name Spots: #REF!
Name Spots: #REF!
Name بسوآهè: [3]çسçرءهآس!$CY$83:$DD$97
Name بسوآهè: [4]çسçرءهآس!$CY$83:$DD$97
Name مشآسطçسçرهآèآوè: [3]çسçرءهآس!$T$6:$AA$23
Name مشآسطçسçرهآèآوè: [4]çسçرءهآس!$T$6:$AA$23

Sheet Shahrdary
C2: برآورد آب موردنیاز آبیاری و خدمات شهری در مناطق شهری | Y2: 0.7 | Z2: 0.3
B3: منطقه | C3: سطح کاربری فضای سبز؛ هکتار | G3: توسعهء تکمیلی فضای سبز | H3: سهم فضاهای سبز متفرقه | I3: فضای سبز مبنای طراحی؛ هکتار | J3: نیاز آبیاری ماه اوج؛ لیتردرثانیه | Q3: نیاز آبیاری؛ هزارمترمکعب | T3: ظرفیت واحد ماه اوج | W3: ظرفیت واحد توسعه | X3: لیتردرثانیه درهکتار | AB3: نیاز آبیاری ماه اوج؛ هزارمترمکعب | AD3: اولیه
C4: وضعِ موجود | D4: درحال توسعه‌ | E4: طرح تفصیلی | F4: پهنه‌های ‌توسعه‌نیافته | J4: وضع موجود | K4: درحال توسعه‌ | L4: طرح تفصیلی | M4: پهنه‌های ‌توسعه‌نیافته | N4: توسعه متفرقه و تکمیلی | O4: خدمات غیرآبیاری | P4: مبنای طراحی | Q4: ماه اوج | R4: سالانه | S4: سهم ماه اوج نسبت به سال | T4: لیتردرثانیه درهکتار | U4: مترمکعب در هکتار | X4: برآیند | Y4: بوستان | Z4: معابر | AA4: جنگل | AC4: مترمکعب در هکتار | AD4: طرح تفصیلی؛ هکتار | AE4: سطوح اضافه‌شده دستی؛ هکتار | AG4: ='[5]Total(forecast)'!$AB$2 -> مجموع مساحت سال 1399 | AH4: نیاز واحد (مترمکعب در هکتار)
C5: بر اساس ارقام خروجی از نرم‌افزار | R5: =HydroM.!K1 -> 0.23
B6: =B34 -> 1 | C6: =HydroM.!W5 -> 54.5911 | D6: =D34 -> 1.1533 | E6: =E34 -> 10.3858 | F6: =F34 -> 0 | G6: 0.1 | H6: 0.05 | I6: =SUM(C6:F6)*(1+G6)*(1+H6) -> 76.380381 | J6: =HydroM.!X5*1000/31/24/3600*1000 -> 63.245714 | K6: =D6*$X6 -> 1.3361387 | L6: =E6*$X6 -> 12.032316 | M6: =F6*$X6 -> 0 | N6: =SUM(J6:M6)*(H6+G6) -> 11.492125 | O6: 0.05 | P6: =SUM(J6:M6)*(1+H6)*(1+O6)*(1+G6) -> 92.913833 | Q6: =P6*3600*24*31/1000/1000 -> 248.86041 | R6: =Q6/$R$5 -> 1082.0018 | S6: =S34 -> 0.23331163 | T6: =P6/I6 -> 1.216462 | U6: =R6*1000/I6 -> 14165.965 | X6: =HydroM.!Z5 -> 1.1585353 | AB6: =J6*3600*24*31/1000/1000 -> 169.39732 | AC6: =R6*1000*(1-O6)/I6 -> 13457.666 | AD6: 23.8 | AG6: 424230 | AH6: 19688.197 | AJ6: =(AG6/10000)-#REF!+AE6 -> #REF! | AK6: =(AH6)-#REF! -> #REF! | AL6: =#REF!-I6 -> #REF! | AM6: =#REF!-P6 -> #REF!
B7: =B35 -> 2 | C7: =HydroM.!W6 -> 142.6064 | D7: =D35 -> 30 | E7: =E35 -> 115.27416 | F7: =F35 -> 0 | G7: =G6 -> 0.1 | H7: =H6 -> 0.05 | I7: =SUM(C7:F7)*(1+G7)*(1+H7) -> 332.50205 | J7: =HydroM.!X6*1000/31/24/3600*1000 -> 140.66792 | K7: =D7*$X7 -> 29.592203 | L7: =E7*$X7 -> 113.70722 | M7: =F7*$X7 -> 0 | N7: =SUM(J7:M7)*(H7+G7) -> 42.595101 | O7: =O6 -> 0.05 | P7: =SUM(J7:M7)*(1+H7)*(1+O7)*(1+G7) -> 344.38139 | Q7: =P7*3600*24*31/1000/1000 -> 922.39112 | R7: =Q7/$R$5 -> 4010.3962 | S7: =S35 -> 0.23069006 | T7: =P7/I7 -> 1.0357271 | U7: =R7*1000/I7 -> 12061.267 | X7: =HydroM.!Z6 -> 0.98640678 | AB7: =J7*3600*24*31/1000/1000 -> 376.76496 | AC7: =R7*1000*(1-O7)/I7 -> 11458.204 | AD7: 180.83485 | AG7: 1290044 | AH7: 15184.222 | AJ7: =(AG7/10000)-#REF!+AE7 -> #REF! | AK7: =(AH7)-#REF! -> #REF! | AL7: =#REF!-I7 -> #REF! | AM7: =#REF!-P7 -> #REF!
B8: =B36 -> 3 | C8: =HydroM.!W7 -> 110.974 | D8: =D36 -> 0 | E8: =E36 -> 147.78486 | F8: =F36 -> 10 | G8: =G7 -> 0.1 | H8: =H7 -> 0.05 | I8: =SUM(C8:F8)*(1+G8)*(1+H8) -> 310.41649 | J8: =HydroM.!X7*1000/31/24/3600*1000 -> 113.18459 | K8: =D8*$X8 -> 0 | L8: =E8*$X8 -> 150.72872 | M8: =F8*$X8 -> 10.199199 | N8: =SUM(J8:M8)*(H8+G8) -> 41.116876 | O8: =O7 -> 0.05 | P8: =SUM(J8:M8)*(1+H8)*(1+O8)*(1+G8) -> 332.42994 | Q8: =P8*3600*24*31/1000/1000 -> 890.38035 | R8: =Q8/$R$5 -> 3871.2189 | S8: =S36 -> 0.22978589 | T8: =P8/I8 -> 1.0709159 | U8: =R8*1000/I8 -> 12471.048 | X8: =HydroM.!Z7 -> 1.0199199 | AB8: =J8*3600*24*31/1000/1000 -> 303.1536 | AC8: =R8*1000*(1-O8)/I8 -> 11847.496 | AD8: 271.3 | AG8: 1036659 | AH8: 14878.665 | AJ8: =(AG8/10000)-#REF!+AE8 -> #REF! | AK8: =(AH8)-#REF! -> #REF! | AL8: =#REF!-I8 -> #REF! | AM8: =#REF!-P8 -> #REF!
B9: =B37 -> 4 | C9: =HydroM.!W8 -> 67.196 | D9: =D37 -> 13.375275 | E9: =E37 -> 67.0136 | F9: =F37 -> 0 | G9: =G8 -> 0.1 | H9: =H8 -> 0.05 | I9: =SUM(C9:F9)*(1+G9)*(1+H9) -> 170.46053 | J9: =HydroM.!X8*1000/31/24/3600*1000 -> 65.710576 | K9: =D9*$X9 -> 13.079603 | L9: =E9*$X9 -> 65.532208 | M9: =F9*$X9 -> 0 | N9: =SUM(J9:M9)*(H9+G9) -> 21.648358 | O9: =O8 -> 0.05 | P9: =SUM(J9:M9)*(1+H9)*(1+O9)*(1+G9) -> 175.02698 | Q9: =P9*3600*24*31/1000/1000 -> 468.79225 | R9: =Q9/$R$5 -> 2038.2272 | S9: =S37 -> 0.22871257 | T9: =P9/I9 -> 1.0267889 | U9: =R9*1000/I9 -> 11957.18 | X9: =HydroM.!Z8 -> 0.97789416 | AB9: =J9*3600*24*31/1000/1000 -> 175.99921 | AC9: =R9*1000*(1-O9)/I9 -> 11359.321 | AD9: 117.5 | AG9: 516710 | AH9: 17309.18 | AJ9: =(AG9/10000)-#REF!+AE9 -> #REF! | AK9: =(AH9)-#REF! -> #REF! | AL9: =#REF!-I9 -> #REF! | AM9: =#REF!-P9 -> #REF!
B10: =B38 -> 5 | C10: =HydroM.!W9 -> 73.1793 | D10: =D38 -> 81.644 | E10: =E38 -> 47.1736 | F10: =F38 -> 23.8 | G10: =G9 -> 0.1 | H10: =H9 -> 0.05 | I10: =SUM(C10:F10)*(1+G10)*(1+H10) -> 260.79542 | J10: =HydroM.!X9*1000/31/24/3600*1000 -> 66.019846 | K10: =D10*$X10 -> 73.656407 | L10: =E10*$X10 -> 42.558398 | M10: =F10*$X10 -> 21.471541 | N10: =SUM(J10:M10)*(H10+G10) -> 30.555929 | O10: =O9 -> 0.05 | P10: =SUM(J10:M10)*(1+H10)*(1+O10)*(1+G10) -> 247.04468 | Q10: =P10*3600*24*31/1000/1000 -> 661.68448 | R10: =Q10/$R$5 -> 2876.889 | S10: =S38 -> 0.23050106 | T10: =P10/I10 -> 0.94727386 | U10: =R10*1000/I10 -> 11031.21 | X10: =HydroM.!Z9 -> 0.90216558 | AB10: =J10*3600*24*31/1000/1000 -> 176.82755 | AC10: =R10*1000*(1-O10)/I10 -> 10479.65 | AD10: 96 | AG10: 452492 | AH10: 20353.955 | AJ10: =(AG10/10000)-#REF!+AE10 -> #REF! | AK10: =(AH10)-#REF! -> #REF! | AL10: =#REF!-I10 -> #REF! | AM10: =#REF!-P10 -> #REF!
B11: =B39 -> 6 | C11: =HydroM.!W10 -> 89.3827 | D11: =D39 -> 5.6 | E11: =E39 -> 150.22809 | F11: =F39 -> 0 | G11: =G10 -> 0.1 | H11: =H10 -> 0.05 | I11: =SUM(C11:F11)*(1+G11)*(1+H11) -> 283.21846 | J11: =HydroM.!X10*1000/31/24/3600*1000 -> 96.05445 | K11: =D11*$X11 -> 6.0179981 | L11: =E11*$X11 -> 161.44149 | M11: =F11*$X11 -> 0 | N11: =SUM(J11:M11)*(H11+G11) -> 39.527091 | O11: =O10 -> 0.05 | P11: =SUM(J11:M11)*(1+H11)*(1+O11)*(1+G11) -> 319.57653 | Q11: =P11*3600*24*31/1000/1000 -> 855.95378 | R11: =Q11/$R$5 -> 3721.5382 | S11: =S39 -> 0.22870889 | T11: =P11/I11 -> 1.1283746 | U11: =R11*1000/I11 -> 13140.168 | X11: =HydroM.!Z10 -> 1.0746425 | Y11: 0.9056387 | Z11: 1.4135314 | AA11: 0.20284312 | AB11: =J11*3600*24*31/1000/1000 -> 257.27224 | AC11: =R11*1000*(1-O11)/I11 -> 12483.16 | AD11: 187.6 | AG11: 784996 | AH11: 16722.498 | AJ11: =(AG11/10000)-#REF!+AE11 -> #REF! | AK11: =(AH11)-#REF! -> #REF! | AL11: =#REF!-I11 -> #REF! | AM11: =#REF!-P11 -> #REF!
B12: =B40 -> 7 | C12: =HydroM.!W11 -> 527.73968 | D12: =D40 -> 0 | E12: =E40 -> 285.43951 | F12: =F40 -> 0 | G12: =G11 -> 0.1 | H12: =H11 -> 0.05 | I12: =SUM(C12:F12)*(1+G12)*(1+H12) -> 939.22196 | J12: =HydroM.!X11*1000/31/24/3600*1000 -> 320.79475 | K12: =D12*$X12 -> 0 | L12: =E12*$X12 -> 173.50883 | M12: =F12*$X12 -> 0 | N12: =SUM(J12:M12)*(H12+G12) -> 74.145537 | O12: =O11 -> 0.05 | P12: =SUM(J12:M12)*(1+H12)*(1+O12)*(1+G12) -> 599.46666 | Q12: =P12*3600*24*31/1000/1000 -> 1605.6115 | R12: =Q12/$R$5 -> 6980.9196 | S12: =S40 -> 0.23620973 | T12: =P12/I12 -> 0.63825878 | U12: =R12*1000/I12 -> 7432.6623 | X12: =HydroM.!Z11 -> 0.60786551 | AB12: =J12*3600*24*31/1000/1000 -> 859.21665 | AC12: =R12*1000*(1-O12)/I12 -> 7061.0292 | AD12: 601.6 | AG12: 4523250 | AH12: 6122.5544 | AJ12: =(AG12/10000)-#REF!+AE12 -> #REF! | AK12: =(AH12)-#REF! -> #REF! | AL12: =#REF!-I12 -> #REF! | AM12: =#REF!-P12 -> #REF!
B13: =B41 -> 8 | C13: =HydroM.!W12 -> 105.1543 | D13: =D41 -> 0 | E13: =E41 -> 79.388788 | F13: =F41 -> 0 | G13: =G12 -> 0.1 | H13: =H12 -> 0.05 | I13: =SUM(C13:F13)*(1+G13)*(1+H13) -> 213.14727 | J13: =HydroM.!X12*1000/31/24/3600*1000 -> 81.523424 | K13: =D13*$X13 -> 0 | L13: =E13*$X13 -> 61.548085 | M13: =F13*$X13 -> 0 | N13: =SUM(J13:M13)*(H13+G13) -> 21.460726 | O13: =O12 -> 0.05 | P13: =SUM(J13:M13)*(1+H13)*(1+O13)*(1+G13) -> 173.50997 | Q13: =P13*3600*24*31/1000/1000 -> 464.72911 | R13: =Q13/$R$5 -> 2020.5613 | S13: =S41 -> 0.23318938 | T13: =P13/I13 -> 0.81403799 | U13: =R13*1000/I13 -> 9479.6494 | X13: =HydroM.!Z12 -> 0.77527428 | AB13: =J13*3600*24*31/1000/1000 -> 218.35234 | AC13: =R13*1000*(1-O13)/I13 -> 9005.6669 | AD13: 283.5 | AG13: 1119727 | AH13: 8814.2903 | AJ13: =(AG13/10000)-#REF!+AE13 -> #REF! | AK13: =(AH13)-#REF! -> #REF! | AL13: =#REF!-I13 -> #REF! | AM13: =#REF!-P13 -> #REF!
B14: =B42 -> 9 | C14: =HydroM.!W13 -> 324.2601 | D14: =D42 -> 0 | E14: =E42 -> 363.696 | F14: =F42 -> 0 | G14: =G13 -> 0.1 | H14: =H13 -> 0.05 | I14: =SUM(C14:F14)*(1+G14)*(1+H14) -> 794.5893 | J14: =HydroM.!X13*1000/31/24/3600*1000 -> 238.38871 | K14: =D14*$X14 -> 0 | L14: =E14*($AA14+Z14)/2 -> 219.49356 | M14: =F14*$X14 -> 0 | N14: =SUM(J14:M14)*(H14+G14) -> 68.682341 | O14: =O13 -> 0.05 | P14: =SUM(J14:M14)*(1+H14)*(1+O14)*(1+G14) -> 555.29672 | Q14: =P14*3600*24*31/1000/1000 -> 1487.3067 | R14: =Q14/$R$5 -> 6466.5511 | S14: =S42 -> 0.23221309 | T14: =P14/I14 -> 0.69884748 | U14: =R14*1000/I14 -> 8138.2308 | X14: =HydroM.!Z13 -> 0.73517743 | Y14: 1.3661978 | Z14: 0.98427729 | AA14: 0.22273936 | AB14: =J14*3600*24*31/1000/1000 -> 638.50031 | AC14: =R14*1000*(1-O14)/I14 -> 7731.3192 | AD14: 1018.5 | AG14: 4185880 | AH14: 8482.2216 | AJ14: =(AG14/10000)-#REF!+AE14 -> #REF! | AK14: =(AH14)-#REF! -> #REF! | AL14: =#REF!-I14 -> #REF! | AM14: =#REF!-P14 -> #REF!
B15: =B43 -> 10 | C15: =HydroM.!W14 -> 189.873 | D15: =D43 -> 0 | E15: =E43 -> 39.023784 | F15: =F43 -> 0 | G15: =G14 -> 0.1 | H15: =H14 -> 0.05 | I15: =SUM(C15:F15)*(1+G15)*(1+H15) -> 264.37579 | J15: =HydroM.!X14*1000/31/24/3600*1000 -> 167.57238 | K15: =D15*$X15 -> 0 | L15: =E15*$X15 -> 34.440433 | M15: =F15*$X15 -> 0 | N15: =SUM(J15:M15)*(H15+G15) -> 30.301922 | O15: =O14 -> 0.05 | P15: =SUM(J15:M15)*(1+H15)*(1+O15)*(1+G15) -> 244.99104 | Q15: =P15*3600*24*31/1000/1000 -> 656.18399 | R15: =Q15/$R$5 -> 2852.9739 | S15: =S43 -> 0.22930325 | T15: =P15/I15 -> 0.92667729 | U15: =R15*1000/I15 -> 10791.359 | X15: =HydroM.!Z14 -> 0.8825498 | Y15: 0.9056387 | Z15: 1.4135314 | AA15: 0.20284312 | AB15: =J15*3600*24*31/1000/1000 -> 448.82586 | AC15: =R15*1000*(1-O15)/I15 -> 10251.791 | AD15: 124.5 | AE15: 1.51 | AG15: 1535818 | AH15: 13805.756 | AJ15: =(AG15/10000)-#REF!+AE15 -> #REF! | AK15: =(AH15)-#REF! -> #REF! | AL15: =#REF!-I15 -> #REF! | AM15: =#REF!-P15 -> #REF!
B16: =B44 -> 11 | C16: =HydroM.!W15 -> 121.606 | D16: =D44 -> 0 | E16: =E44 -> 162.86718 | F16: =F44 -> 0 | G16: =G15 -> 0.1 | H16: =H15 -> 0.05 | I16: =SUM(C16:F16)*(1+G16)*(1+H16) -> 328.56652 | J16: =HydroM.!X15*1000/31/24/3600*1000 -> 135.98005 | K16: =D16*$X16 -> 0 | L16: =E16*$X16 -> 182.11837 | M16: =F16*$X16 -> 0 | N16: =SUM(J16:M16)*(H16+G16) -> 47.714762 | O16: =O15 -> 0.05 | P16: =SUM(J16:M16)*(1+H16)*(1+O16)*(1+G16) -> 385.77385 | Q16: =P16*3600*24*31/1000/1000 -> 1033.2567 | R16: =Q16/$R$5 -> 4492.4204 | S16: =S44 -> 0.22857703 | T16: =P16/I16 -> 1.1741119 | U16: =R16*1000/I16 -> 13672.788 | X16: =HydroM.!Z15 -> 1.1182018 | Y16: 1.6802586 | Z16: 1.5804142 | AA16: 0.12517512 | AB16: =J16*3600*24*31/1000/1000 -> 364.20895 | AC16: =R16*1000*(1-O16)/I16 -> 12989.149 | AG16: 1096369 | AH16: 17361.295 | AJ16: =(AG16/10000)-#REF!+AE16 -> #REF! | AK16: =(AH16)-#REF! -> #REF! | AL16: =#REF!-I16 -> #REF! | AM16: =#REF!-P16 -> #REF!
B17: =B45 -> 12 | C17: =HydroM.!W16 -> 123.7588 | D17: =D45 -> 60 | E17: =E45 -> 344.33338 | F17: =F45 -> 40 | G17: =G16 -> 0.1 | H17: =H16 -> 0.05 | I17: =SUM(C17:F17)*(1+G17)*(1+H17) -> 656.14646 | J17: =HydroM.!X16*1000/31/24/3600*1000 -> 88.545304 | K17: =D17*$X17 -> 42.928004 | L17: =E17*$X17 -> 246.35908 | M17: =F17*$X17 -> 28.618669 | N17: =SUM(J17:M17)*(H17+G17) -> 60.967658 | O17: =O16 -> 0.05 | P17: =SUM(J17:M17)*(1+H17)*(1+O17)*(1+G17) -> 492.92352 | Q17: =P17*3600*24*31/1000/1000 -> 1320.2463 | R17: =Q17/$R$5 -> 5740.2015 | S17: =S45 -> 0.23518908 | T17: =P17/I17 -> 0.75124007 | U17: =R17*1000/I17 -> 8748.3539 | X17: =HydroM.!Z16 -> 0.71546673 | Y17: 1.2430307 | Z17: 1.5334128 | AA17: 0.18708024 | AB17: =J17*3600*24*31/1000/1000 -> 237.15974 | AC17: =R17*1000*(1-O17)/I17 -> 8310.9362 | AD17: 394.84461 | AE17: 0.12 | AG17: 854013 | AH17: 11949.044 | AJ17: =(AG17/10000)-#REF!+AE17 -> #REF! | AK17: =(AH17)-#REF! -> #REF! | AL17: =#REF!-I17 -> #REF! | AM17: =#REF!-P17 -> #REF!
B18: =B46 -> 13 | C18: =HydroM.!W17 -> 9.1693 | D18: =D46 -> 0 | E18: =E46 -> 0 | F18: =F46 -> 0 | G18: =G17 -> 0.1 | H18: =H17 -> 0.05 | I18: =SUM(C18:F18)*(1+G18)*(1+H18) -> 10.590542 | J18: =HydroM.!X17*1000/31/24/3600*1000 -> 11.109159 | K18: =D18*$X18 -> 0 | L18: =E18*$X18 -> 0 | M18: =F18*$X18 -> 0 | N18: =SUM(J18:M18)*(H18+G18) -> 1.6663739 | O18: =O17 -> 0.05 | P18: =SUM(J18:M18)*(1+H18)*(1+O18)*(1+G18) -> 13.472633 | Q18: =P18*3600*24*31/1000/1000 -> 36.0851 | R18: =Q18/$R$5 -> 156.89174 | S18: =S46 -> 0.2345117 | T18: =P18/I18 -> 1.2721382 | U18: =R18*1000/I18 -> 14814.326 | X18: =HydroM.!Z17 -> 1.2115602 | AB18: =J18*3600*24*31/1000/1000 -> 29.754772 | AC18: =R18*1000*(1-O18)/I18 -> 14073.61 | AD18: 0 | AG18: 72237 | AH18: 20774.763 | AJ18: =(AG18/10000)-#REF!+AE18 -> #REF! | AK18: =(AH18)-#REF! -> #REF! | AL18: =#REF!-I18 -> #REF! | AM18: =#REF!-P18 -> #REF!
B19: 7.1 | C19: ='16'!D5/10000 -> 8.111 | D19: 0 | E19: 0 | F19: 0 | G19: 0 | H19: 0 | I19: =SUM(C19:F19)*(1+G19)*(1+H19) -> 8.111 | J19: ='16'!M5*1000/31/24/3600*1000 -> 6.355678 | K19: =D19*$X19 -> 0 | L19: =E19*$X19 -> 0 | M19: =F19*$X19 -> 0 | N19: =SUM(J19:M19)*(H19+G19) -> 0 | O19: 0.05 | P19: =SUM(J19:M19)*(1+H19)*(1+O19)*(1+G19) -> 6.6734619 | Q19: =P19*3600*24*31/1000/1000 -> 17.8742 | R19: =Q19/$R$5 -> 77.713914 | S19: =Q19/R19 -> 0.23 | T19: =P19/I19 -> 0.82276685 | U19: =R19*1000/I19 -> 9581.2988 | AB19: =J19*3600*24*31/1000/1000 -> 17.023048 | AC19: =R19*1000*(1-O19)/I19 -> 9102.2339
B20: 7.2 | C20: ='16'!D6/10000 -> 17.4768 | D20: 0 | E20: 0 | F20: 0 | G20: 0 | H20: 0 | I20: =SUM(C20:F20)*(1+G20)*(1+H20) -> 17.4768 | J20: ='16'!M6*1000/31/24/3600*1000 -> 19.00916 | K20: =D20*$X20 -> 0 | L20: =E20*$X20 -> 0 | M20: =F20*$X20 -> 0 | N20: =SUM(J20:M20)*(H20+G20) -> 0 | O20: =O19 -> 0.05 | P20: =SUM(J20:M20)*(1+H20)*(1+O20)*(1+G20) -> 19.959618 | Q20: =P20*3600*24*31/1000/1000 -> 53.45984 | R20: =Q20/$R$5 -> 232.43409 | S20: =Q20/R20 -> 0.23 | T20: =P20/I20 -> 1.1420636 | U20: =R20*1000/I20 -> 13299.579 | AB20: =J20*3600*24*31/1000/1000 -> 50.914133 | AC20: =R20*1000*(1-O20)/I20 -> 12634.6
B21: 10 | C21: ='16'!D7/10000 -> 1.3428 | D21: 0 | E21: 0 | F21: 0 | G21: 0 | H21: 0 | I21: =SUM(C21:F21)*(1+G21)*(1+H21) -> 1.3428 | J21: ='16'!M7*1000/31/24/3600*1000 -> 1.5763398 | K21: =D21*$X21 -> 0 | L21: =E21*$X21 -> 0 | M21: =F21*$X21 -> 0 | N21: =SUM(J21:M21)*(H21+G21) -> 0 | O21: =O20 -> 0.05 | P21: =SUM(J21:M21)*(1+H21)*(1+O21)*(1+G21) -> 1.6551568 | Q21: =P21*3600*24*31/1000/1000 -> 4.4331719 | R21: =Q21/$R$5 -> 19.27466 | S21: =Q21/R21 -> 0.23 | T21: =P21/I21 -> 1.232616 | U21: =R21*1000/I21 -> 14354.081 | AB21: =J21*3600*24*31/1000/1000 -> 4.2220685 | AC21: =R21*1000*(1-O21)/I21 -> 13636.377
B22: 11 | C22: ='16'!D8/10000 -> 1.3334 | D22: 0 | E22: 0 | F22: 0 | G22: 0 | H22: 0 | I22: =SUM(C22:F22)*(1+G22)*(1+H22) -> 1.3334 | J22: ='16'!M8*1000/31/24/3600*1000 -> 1.5653049 | K22: =D22*$X22 -> 0 | L22: =E22*$X22 -> 0 | M22: =F22*$X22 -> 0 | N22: =SUM(J22:M22)*(H22+G22) -> 0 | O22: =O21 -> 0.05 | P22: =SUM(J22:M22)*(1+H22)*(1+O22)*(1+G22) -> 1.6435702 | Q22: =P22*3600*24*31/1000/1000 -> 4.4021384 | R22: =Q22/$R$5 -> 19.139732 | S22: =Q22/R22 -> 0.23 | T22: =P22/I22 -> 1.232616 | U22: =R22*1000/I22 -> 14354.081 | AB22: =J22*3600*24*31/1000/1000 -> 4.1925127 | AC22: =R22*1000*(1-O22)/I22 -> 13636.377
B23: 12 | C23: ='16'!D9/10000 -> 5.4 | D23: 0 | E23: 0 | F23: 0 | G23: 0 | H23: 0 | I23: =SUM(C23:F23)*(1+G23)*(1+H23) -> 5.4 | J23: ='16'!M9*1000/31/24/3600*1000 -> 6.339168 | K23: =D23*$X23 -> 0 | L23: =E23*$X23 -> 0 | M23: =F23*$X23 -> 0 | N23: =SUM(J23:M23)*(H23+G23) -> 0 | O23: =O22 -> 0.05 | P23: =SUM(J23:M23)*(1+H23)*(1+O23)*(1+G23) -> 6.6561264 | Q23: =P23*3600*24*31/1000/1000 -> 17.827769 | R23: =Q23/$R$5 -> 77.512039 | S23: =Q23/R23 -> 0.23 | T23: =P23/I23 -> 1.232616 | U23: =R23*1000/I23 -> 14354.081 | X23: =HydroM.!Z20 -> 0.79805576 | AB23: =J23*3600*24*31/1000/1000 -> 16.978828 | AC23: =R23*1000*(1-O23)/I23 -> 13636.377 | AL23: =#REF!-I23 -> #REF! | AM23: =#REF!-P23 -> #REF!
B24: - | C24: =SUM(C6:C23) -> 1973.1547 | D24: =SUM(D6:D23) -> 191.77258 | E24: =SUM(E6:E23) -> 1812.6088 | F24: =SUM(F6:F23) -> 73.8 | G24: =SUM($C24:$F24)*(G25) -> 398.22161 | H24: =SUM($C24:$G24)*(H25) -> 218.68218 | I24: =SUM(I6:I23) -> 4674.0752 | J24: =SUM(J6:J23) -> 1623.6425 | K24: =SUM(K6:K23) -> 166.61035 | L24: =SUM(L6:L23) -> 1463.4687 | M24: =SUM(M6:M23) -> 60.289409 | N24: =SUM(N6:N23) -> 491.8748 | O24: =SUM($J24:$N24)*(O25) -> 190.29429 | P24: =SUM(P6:P23) -> 4013.3957 | Q24: =SUM(Q6:Q23) -> 10749.479 | R24: =SUM(R6:R23) -> 46736.865 | S24: =SUMPRODUCT(S6:S23,I6:I23)/I24 -> 0.23236045 | T24: =SUMPRODUCT(T6:T23,I6:I23)/I24 -> 0.85865022 | U24: =ROUND(SUMPRODUCT(U6:U23,I6:I23)/I24,-1) -> 10000 | X24: =SUMPRODUCT(X6:X23,I6:I23)/I24 -> 0.82306241 | AB24: =J24*3600*24*31/1000/1000 -> 4348.7641 | AC24: =ROUND(SUMPRODUCT(AC6:AC23,I6:I23)/I24,-1) -> 9500
C25: حجم نیاز سالانه | E25: میلیون مترمکعب | G25: =SUMPRODUCT(G6:G23,$C6:$C23)/$C24 -> 0.0982939 | H25: =SUMPRODUCT(H6:H23,$C6:$C23)/$C24 -> 0.04914695 | J25: =J24/1000*3600*24*31/S24/1000/1000 -> 18.715595 | O25: =SUMPRODUCT(O6:O23,$C6:$C23)/$C24 -> 0.05 | P25: =P24/J24 -> 2.4718469 | R25: =R24/1000 -> 46.736865 | U25: =U24*I24/1000/1000 -> 46.740752 | AC25: =AC24*I24/1000/1000 -> 44.403714
B27: =B47 -> 14 | C27: 3500 | D27: =D47 -> 0 | E27: =9931-C27-1 -> 6430 | F27: =F47 -> 0 | G27: 0 | H27: 0 | I27: =SUM(C27:F27)*(1+G27)*(1+H27) -> 9930 | J27: =HydroM.!X18*1000/31/24/3600*1000 -> 0 | K27: =D27*$X27 -> 0 | L27: =E27*$X27 -> 0 | M27: =F27*$X27 -> 0 | N27: =SUM(J27:M27)*(H27+G27) -> 0 | O27: 0 | P27: =SUM(J27:M27)*(1+H27)*(1+O27)*(1+G27) -> 0 | Q27: =U27*I27/1000 -> 14895 | R27: =Q27/$R$5 -> 64760.87 | S27: =S47 -> 0 | T27: 0.23 | U27: 1500 | V27: =U27*1000/31/24/3600 -> 0.56003584 | X27: =HydroM.!Z18 -> 0 | AB27: =J27*3600*24*31/1000/1000 -> 0 | AL27: =#REF!-I27 -> #REF! | AM27: =#REF!-P27 -> #REF!
B28: =B48 -> 15 | C28: 181 | D28: =D48 -> 0 | E28: =536-C28-1 -> 354 | F28: =F48 -> 0 | G28: 0 | H28: 0 | I28: =SUM(C28:F28)*(1+G28)*(1+H28) -> 535 | J28: =HydroM.!X19*1000/31/24/3600*1000 -> 0 | K28: =D28*$X28 -> 0 | L28: =E28*$X28 -> 0 | M28: =F28*$X28 -> 0 | N28: =SUM(J28:M28)*(H28+G28) -> 0 | O28: 0 | P28: =SUM(J28:M28)*(1+H28)*(1+O28)*(1+G28) -> 0 | Q28: =U28*I28/1000 -> 802.5 | R28: =Q28/$R$5 -> 3489.1304 | S28: =S48 -> 0 | T28: 0.23 | U28: 1500 | X28: =HydroM.!Z19 -> 0 | AB28: =J28*3600*24*31/1000/1000 -> 0 | AL28: =#REF!-I28 -> #REF! | AM28: =#REF!-P28 -> #REF!
I29: =SUM(I14:I17) -> 2043.6781 | J29: =SUM(J14:J17) -> 630.48644 | K29: =SUM(K14:K17) -> 42.928004 | L29: =SUM(L14:L17) -> 682.41144 | M29: =SUM(M14:M17) -> 28.618669 | N29: =SUM(N14:N17) -> 207.66668 | P29: =SUM(P14:P17) -> 1678.9851
G30: =G25*H24 -> 21.495125 | H30: =H25*G24 -> 19.571378 | P30: =P29*1.5 -> 2518.4777
H31: =(SUM($C24:$F24)*(G25))*H25 -> 19.571378
C33: برآورد از روش دفتر محیط زیست- کاربرگی
B34: =B75 -> 1 | C34: =E75 -> 42.423 | D34: =F75 -> 1.1533 | E34: =G75 -> 10.3858 | F34: =H75 -> 0 | G34: =D75 -> 0.15 | H34: 0.2 | I34: =SUM(C34:F34)*(1+G34)*(1+H34) -> 74.467698 | J34: =J75 -> 72.755909 | K34: =K75 -> 0 | L34: =L75 -> 0 | M34: =M75 -> 0 | O34: 0.05 | P34: =SUM(J34:M34)*(1+H34)*(1+O34)*(1+G34) -> 105.42331 | Q34: =O75*(1+H34) -> 282.3658 | R34: =P75*(1+H34) -> 1210.2517 | S34: =S75 -> 0.23331163 | T34: =Q75*(1+O34) -> 1.8007615 | U34: =R34*1000/I34 -> 16252.036 | X34: =J34/C34 -> 1.7150109 | AC34: =ROUND(R75,-1) -> 19690 | AD34: 23.8 | AG34: 424230 | AH34: 19688.197 | AJ34: =(AG34/10000)-E75+AE34 -> 0 | AK34: =(AH34)-R75 -> 0 | AL34: =I75-I34 -> -25.681248 | AM34: =N75-P34 -> -17.570552
B35: =B76 -> 2 | C35: =E76 -> 129.0044 | D35: =F76 -> 30 | E35: =G76 -> 115.27416 | F35: =H76 -> 0 | G35: =G34 -> 0.15 | H35: =H34 -> 0.2 | I35: =SUM(C35:F35)*(1+G35)*(1+H35) -> 378.50442 | J35: =J76 -> 155.55246 | K35: =K76 -> 0 | L35: =E35*X35 -> 138.99665 | M35: =M76 -> 0 | O35: =O34 -> 0.05 | P35: =SUM(J35:M35)*(1+H35)*(1+O35)*(1+G35) -> 426.80165 | Q35: =O76*(1+H35)*(J35+L35)/J35 -> 1143.1455 | R35: =P76*(1+H35)*(J35+L35)/J35 -> 4955.3307 | S35: =S76 -> 0.23069006 | T35: =Q76*(1+O35) -> 1.2660815 | U35: =R35*1000/I35 -> 13091.87 | X35: =J35/C35 -> 1.2057919 | AC35: =ROUND(R76,-1) -> 14000 | AD35: 180.83485 | AG35: 1290044 | AH35: 15184.222 | AJ35: =(AG35/10000)-E76+AE35 -> 0 | AK35: =(AH35)-R76 -> 1184.5165 | AL35: =I76-I35 -> -230.14936 | AM35: =N76-P35 -> -238.97206
B36: =B77 -> 3 | C36: =E77 -> 103.6659 | D36: =F77 -> 0 | E36: =G77 -> 147.78486 | F36: =H77 -> 10 | G36: =G35 -> 0.15 | H36: =H35 -> 0.2 | I36: =SUM(C36:F36)*(1+G36)*(1+H36) -> 360.80205 | J36: =J77 -> 122.01481 | K36: =K77 -> 0 | L36: =L77 -> 173.94285 | M36: =M77 -> 0 | O36: =O35 -> 0.05 | P36: =SUM(J36:M36)*(1+H36)*(1+O36)*(1+G36) -> 428.84264 | Q36: =O77*(1+H36) -> 1148.6121 | R36: =P77*(1+H36) -> 4998.619 | S36: =S77 -> 0.22978589 | T36: =Q77*(1+O36) -> 1.2358505 | U36: =R36*1000/I36 -> 13854.187 | X36: =J36/C36 -> 1.1770004 | AC36: =ROUND(R77,-1) -> 13720 | AD36: 271.3 | AG36: 1036659 | AH36: 14878.665 | AJ36: =(AG36/10000)-E77+AE36 -> 0 | AK36: =(AH36)-R77 -> 1159.4679 | AL36: =I77-I36 -> -71.633675 | AM36: =N77-P36 -> -71.473774
B37: =B78 -> 4 | C37: =E78 -> 51.671 | D37: =F78 -> 13.375275 | E37: =G78 -> 67.0136 | F37: =H78 -> 0 | G37: =G36 -> 0.15 | H37: =H36 -> 0.2 | I37: =SUM(C37:F37)*(1+G37)*(1+H37) -> 182.24263 | J37: =J78 -> 76.372668 | K37: =K78 -> 19.769415 | L37: =L78 -> 99.049901 | M37: =M78 -> 0 | O37: =O36 -> 0.05 | P37: =SUM(J37:M37)*(1+H37)*(1+O37)*(1+G37) -> 282.83319 | Q37: =O78*(1+H37) -> 757.5404 | R37: =P78*(1+H37) -> 3312.194 | S37: =S78 -> 0.22871257 | T37: =Q78*(1+O37) -> 1.5519595 | U37: =R37*1000/I37 -> 18174.639 | X37: =J37/C37 -> 1.4780567 | AC37: =ROUND(R78,-1) -> 17310 | AD37: 117.5 | AG37: 516710 | AH37: 17309.18 | AJ37: =(AG37/10000)-E78+AE37 -> 0 | AK37: =(AH37)-R78 -> 0 | AL37: =I78-I37 -> -30.373771 | AM37: =N78-P37 -> -47.138864
B38: =B79 -> 5 | C38: =E79 -> 45.2492 | D38: =F79 -> 81.644 | E38: =G79 -> 47.1736 | F38: =H79 -> 23.8 | G38: =G37 -> 0.15 | H38: =H37 -> 0.2 | I38: =SUM(C38:F38)*(1+G38)*(1+H38) -> 273.05618 | J38: =J79 -> 73.086671 | K38: =K79 -> 131.87168 | L38: =L79 -> 76.194969 | M38: =M79 -> 38.441846 | O38: =O37 -> 0.05 | P38: =SUM(J38:M38)*(1+H38)*(1+O38)*(1+G38) -> 463.0934 | Q38: =O79*(1+H38) -> 1240.3494 | R38: =P79*(1+H38) -> 5381.1006 | S38: =S79 -> 0.23050106 | T38: =Q79*(1+O38) -> 1.6959638 | U38: =R38*1000/I38 -> 19706.935 | X38: =J38/C38 -> 1.6152036 | AC38: =ROUND(R79,-1) -> 18770 | AD38: 96 | AG38: 452492 | AH38: 20353.955 | AJ38: =(AG38/10000)-E79+AE38 -> 0 | AK38: =(AH38)-R79 -> 1585.4451 | AL38: =I79-I38 -> -45.509364 | AM38: =N79-P38 -> -77.182233
B39: =B80 -> 6 | C39: =E80 -> 78.4996 | D39: =F80 -> 5.6 | E39: =G80 -> 150.22809 | F39: =H80 -> 0 | G39: =G38 -> 0.15 | H39: =H38 -> 0.2 | I39: =SUM(C39:F39)*(1+G39)*(1+H39) -> 323.37221 | J39: =J80 -> 103.37367 | K39: =K80 -> 7.374465 | L39: =L80 -> 197.83068 | M39: =M80 -> 0 | O39: =O38 -> 0.05 | P39: =SUM(J39:M39)*(1+H39)*(1+O39)*(1+G39) -> 447.1307 | Q39: =O80*(1+H39) -> 1197.5949 | R39: =P80*(1+H39) -> 5236.3285 | S39: =S80 -> 0.22870889 | T39: =Q80*(1+O39) -> 1.3827122 | U39: =R39*1000/I39 -> 16192.883 | X39: =J39/C39 -> 1.3168688 | AC39: =ROUND(R80,-1) -> 15420 | AD39: 187.6 | AG39: 784996 | AH39: 16722.498 | AJ39: =(AG39/10000)-E80+AE39 -> 0 | AK39: =(AH39)-R80 -> 1300.7041 | AL39: =I80-I39 -> -53.895369 | AM39: =N80-P39 -> -74.521783
B40: =B81 -> 7 | C40: =E81 -> 452.325 | D40: =F81 -> 0 | E40: =G81 -> 285.43951 | F40: =H81 -> 0 | G40: =G39 -> 0.15 | H40: =H39 -> 0.2 | I40: =SUM(C40:F40)*(1+G40)*(1+H40) -> 1018.115 | J40: =J81 -> 244.2337 | K40: =K81 -> 0 | L40: =L81 -> 155.0584 | M40: =M81 -> 0 | O40: =O39 -> 0.05 | P40: =SUM(J40:M40)*(1+H40)*(1+O40)*(1+G40) -> 578.57425 | Q40: =O81*(1+H40) -> 1549.6533 | R40: =P81*(1+H40) -> 6560.4972 | S40: =S81 -> 0.23620973 | T40: =Q81*(1+O40) -> 0.57038818 | U40: =R40*1000/I40 -> 6443.7682 | X40: =J40/C40 -> 0.53995181 | AC40: =ROUND(R81,-1) -> 6160 | AD40: 601.6 | AG40: 4523250 | AH40: 6122.5544 | AJ40: =(AG40/10000)-E81+AE40 -> 0 | AK40: =(AH40)-R81 -> -37.135854 | AL40: =I81-I40 -> -172.82189 | AM40: =N81-P40 -> -96.429042
B41: =B82 -> 8 | C41: =E82 -> 188.9336 | D41: =F82 -> 0 | E41: =G82 -> 79.388788 | F41: =H82 -> 0 | G41: =G40 -> 0.15 | H41: =H40 -> 0.2 | I41: =SUM(C41:F41)*(1+G41)*(1+H41) -> 370.2849 | J41: =J82 -> 171.85526 | K41: =K82 -> 0 | L41: =L82 -> 72.212568 | M41: =M82 -> 0 | O41: =O40 -> 0.05 | P41: =SUM(J41:M41)*(1+H41)*(1+O41)*(1+G41) -> 353.65428 | Q41: =O82*(1+H41) -> 947.22762 | R41: =P82*(1+H41) -> 4062.053 | S41: =S82 -> 0.23318938 | T41: =Q82*(1+O41) -> 0.95508697 | U41: =R41*1000/I41 -> 10970.075 | X41: =J41/C41 -> 0.90960664 | AC41: =ROUND(R82,-1) -> 10450 | AD41: 283.5 | AG41: 1119727 | AH41: 8814.2903 | AJ41: =(AG41/10000)-E82+AE41 -> -76.9609 | AK41: =(AH41)-R82 -> -1633.4001 | AL41: =I82-I41 -> -61.714149 | AM41: =N82-P41 -> -58.94238
B42: =B83 -> 9 | C42: =E83 -> 418.588 | D42: =F83 -> 0 | E42: =G83 -> 363.696 | F42: =H83 -> 0 | G42: =G41 -> 0.15 | H42: =H41 -> 0.2 | I42: =SUM(C42:F42)*(1+G42)*(1+H42) -> 1079.5519 | J42: =J83 -> 283.805 | K42: =K83 -> 0 | L42: =E42*X42 -> 246.58792 | M42: =M83 -> 0 | O42: =O41 -> 0.05 | P42: =SUM(J42:M42)*(1+H42)*(1+O42)*(1+G42) -> 768.53935 | Q42: =O83*(1+H42)*(J42+L42)/J42 -> 2058.4558 | R42: =P83*(1+H42)*(J42+L42)/J42 -> 8864.5124 | S42: =S83 -> 0.23221309 | T42: =Q83*(1+O42) -> 0.71190587 | U42: =R42*1000/I42 -> 8211.2886 | X42: =J42/C42 -> 0.67800559 | AC42: =ROUND(R83,-1) -> 7820 | AD42: 1018.5 | AG42: 4185880 | AH42: 8482.2216 | AJ42: =(AG42/10000)-E83+AE42 -> 0 | AK42: =(AH42)-R83 -> 661.94667 | AL42: =I83-I42 -> -598.17572 | AM42: =N83-P42 -> -425.84481
B43: =B84 -> 10 | C43: =E84 -> 157.2299 | D43: =F84 -> 0 | E43: =G84 -> 39.023784 | F43: =H84 -> 0 | G43: =G42 -> 0.15 | H43: =H42 -> 0.2 | I43: =SUM(C43:F43)*(1+G43)*(1+H43) -> 270.83008 | J43: =J84 -> 170.62454 | K43: =K84 -> 0 | L43: =L84 -> 42.758922 | M43: =M84 -> 0 | O43: =O42 -> 0.05 | P43: =SUM(J43:M43)*(1+H43)*(1+O43)*(1+G43) -> 309.19263 | Q43: =O84*(1+H43) -> 828.14154 | R43: =P84*(1+H43) -> 3611.556 | S43: =S84 -> 0.22930325 | T43: =Q84*(1+O43) -> 1.1505001 | U43: =R43*1000/I43 -> 13335.136 | X43: =J43/C43 -> 1.0851914 | AC43: =ROUND(R84,-1) -> 12800 | AD43: 124.5 | AE43: 1.51 | AG43: 1535818 | AH43: 13805.756 | AJ43: =(AG43/10000)-E84+AE43 -> -2.1381 | AK43: =(AH43)-R84 -> 1007.1523 | AL43: =I84-I43 -> -46.874847 | AM43: =N84-P43 -> -51.532105
...

Sheet HydroM.
K1: 0.23 | L1: سهم ماه اوج | X1: 0.23334398 | AE1: 0.22141923 | AF1: سهم ماه اوج
B2: از برآورد مهندسی- با تعدیل سطح سایه‌انداز | K2: 10 | L2: سطح مفروض درختان | O2: از روش دفتر محیط زیست- محاسبات کاربرگی | W2: از روش دفتر محیط زیست- محاسبات نرم‌افزاری | AE2: از روش سه‌ضریبی
B3: منطقه شهرداری | C3: مساحت پهنه | D3: فضای سبز (نگهداری) | E3: سطوح آبیاری لکه‌ها | F3: سطح نگهداری تک‌درختان | G3: سطح تبخیرتعرق تک‌درختان | H3: سطح برآورد تبخیرتعرق | I3: نیاز آبیاری لکه‌ها | J3: نیازآبیاری تک‌درختان | K3: هزار مترمکعب؛ ماه اوج | L3: مترمکعب در هکتار سالانه | M3: لیتردرثانیه درهکتار؛ ماه اوج | O3: =Shahrdary!C4 -> وضعِ موجود | P3: =Shahrdary!J3 -> نیاز آبیاری ماه اوج؛ لیتردرثانیه | Q3: هزار مترمکعب؛ ماه اوج | R3: مترمکعب در هکتار سالانه | S3: لیتردرثانیه درهکتار؛ ماه اوج | U3: اختلاف در سطح | W3: فضای سبز (نگهداری) | X3: هزار مترمکعب؛ ماه اوج | Y3: مترمکعب در هکتار سالانه | Z3: لیتردرثانیه درهکتار؛ ماه اوج | AA3: اختلاف در سطح | AB3: اختلاف در سطح | AC3: اختلاف در سطح | AE3: فضای سبز (نگهداری) | AF3: هزار مترمکعب؛ ماه اوج | AG3: مترمکعب در هکتار سالانه | AH3: لیتردرثانیه درهکتار؛ ماه اوج
C4: هکتار | D4: هکتار | E4: هکتار | F4: هکتار | G4: هکتار | H4: هکتار | I4: هزارمترمکعب درروز | O4: هکتار | U4: هکتار | W4: هکتار | AB4: هکتار | AC4: هزار مترمکعب | AE4: هکتار
B5: 1 | C5: 1478.9601 | D5: 42.5879 | E5: 37.9843 | F5: 4.6051 | G5: 16.6068 | H5: 54.5911 | I5: 2.9249241 | J5: 0.33001033 | K5: =(J5*$K$2/9+I5)*31 -> 102.03967 | L5: =K5/D5/$K$1*1000 -> 10417.295 | M5: =L5*1000/31/24/3600*$K$1 -> 0.89455569 | O5: =Shahrdary!C34 -> 42.423 | P5: =Shahrdary!J34 -> 72.755909 | Q5: =P5*3600*24*31/1000/1000 -> 194.86943 | R5: =Q5*1000/O5/$K$1 -> 19971.675 | S5: =R5*1000/31/24/3600*$K$1 -> 1.7150109 | U5: =O5-D5 -> -0.1649 | W5: 54.5911 | X5: 169.39732 | Y5: =X5*1000/W5/$K$1 -> 13491.395 | Z5: =Y5*1000/31/24/3600*$K$1 -> 1.1585353 | AA5: =W5-D5 -> 12.0032 | AB5: =W5-O5 -> 12.1681 | AC5: =X5-Q5 -> -25.472105 | AD5: =Z5*W5 -> 63.245714 | AE5: 54.5911 | AF5: 158.29005 | AG5: =AF5*1000/AE5/$K$1 -> 12606.773 | AH5: =AG5*1000/31/24/3600*$K$1 -> 1.0825708
B6: 2 | C6: 3848.8489 | D6: 124.5886 | E6: 79.2967 | F6: 45.3012 | G6: 63.3097 | H6: 142.6064 | I6: 5.7405296 | J6: 1.2580904 | K6: =(J6*$K$2/9+I6)*31 -> 221.29064 | L6: =K6/D6/$K$1*1000 -> 7722.482 | M6: =L6*1000/31/24/3600*$K$1 -> 0.66314623 | O6: =Shahrdary!C35 -> 129.0044 | P6: =Shahrdary!J35 -> 155.55246 | Q6: =P6*3600*24*31/1000/1000 -> 416.6317 | R6: =Q6*1000/O6/$K$1 -> 14041.708 | S6: =R6*1000/31/24/3600*$K$1 -> 1.2057919 | U6: =O6-D6 -> 4.4158 | W6: 142.6064 | X6: 376.76496 | Y6: =X6*1000/W6/$K$1 -> 11486.921 | Z6: =Y6*1000/31/24/3600*$K$1 -> 0.98640678 | AA6: =W6-D6 -> 18.0178 | AB6: =W6-O6 -> 13.602 | AC6: =X6-Q6 -> -39.866741 | AD6: =Z6*W6 -> 140.66792 | AE6: 142.6064 | AF6: 380.50879 | AG6: =AF6*1000/AE6/$K$1 -> 11601.064 | AH6: =AG6*1000/31/24/3600*$K$1 -> 0.99620849 | AJ6: =1/AK6^0.5 -> 2.236068 | AK6: 0.2
B7: 3 | C7: 3311.0005 | D7: 103.5865 | E7: 71.1002 | F7: 32.7541 | G7: 39.8738 | H7: 110.974 | I7: 4.7381364 | J7: 0.79237215 | K7: =(J7*$K$2/9+I7)*31 -> 174.17505 | L7: =K7/D7/$K$1*1000 -> 7310.6323 | M7: =L7*1000/31/24/3600*$K$1 -> 0.62777981 | O7: =Shahrdary!C36 -> 103.6659 | P7: =Shahrdary!J36 -> 122.01481 | Q7: =P7*3600*24*31/1000/1000 -> 326.80446 | R7: =Q7*1000/O7/$K$1 -> 13706.426 | S7: =R7*1000/31/24/3600*$K$1 -> 1.1770004 | U7: =O7-D7 -> 0.0794 | W7: 110.974 | X7: 303.1536 | Y7: =X7*1000/W7/$K$1 -> 11877.189 | Z7: =Y7*1000/31/24/3600*$K$1 -> 1.0199199 | AA7: =W7-D7 -> 7.3875 | AB7: =W7-O7 -> 7.3081 | AC7: =X7-Q7 -> -23.650865 | AD7: =Z7*W7 -> 113.18459 | AE7: 110.974 | AF7: 227.82645 | AG7: =AF7*1000/AE7/$K$1 -> 8925.9628 | AH7: =AG7*1000/31/24/3600*$K$1 -> 0.76649173 | AJ7: =1/AK7^0.5 -> 1.4142136 | AK7: 0.5
B8: 4 | C8: 1344.8622 | D8: 51.905 | E8: 40.0097 | F8: 11.8632 | G8: 27.1863 | H8: 67.196 | I8: 2.6532464 | J8: 0.54024615 | K8: =(J8*$K$2/9+I8)*31 -> 100.85912 | L8: =K8/D8/$K$1*1000 -> 8448.4711 | M8: =L8*1000/31/24/3600*$K$1 -> 0.72548849 | O8: =Shahrdary!C37 -> 51.671 | P8: =Shahrdary!J37 -> 76.372668 | Q8: =P8*3600*24*31/1000/1000 -> 204.55655 | R8: =Q8*1000/O8/$K$1 -> 17212.292 | S8: =R8*1000/31/24/3600*$K$1 -> 1.4780567 | U8: =O8-D8 -> -0.234 | W8: 67.196 | X8: 175.99921 | Y8: =X8*1000/W8/$K$1 -> 11387.79 | Z8: =Y8*1000/31/24/3600*$K$1 -> 0.97789416 | AA8: =W8-D8 -> 15.291 | AB8: =W8-O8 -> 15.525 | AC8: =X8-Q8 -> -28.557348 | AD8: =Z8*W8 -> 65.710576 | AE8: 67.196 | AF8: 149.06105 | AG8: =AF8*1000/AE8/$K$1 -> 9644.7934 | AH8: =AG8*1000/31/24/3600*$K$1 -> 0.82821927 | AJ8: =1/AK8^0.5 -> 1.1547005 | AK8: 0.75
B9: 5 | C9: 1438.7993 | D9: 44.6798 | E9: 36.6456 | F9: 8.0442 | G9: 36.5337 | H9: 73.1793 | I9: 2.5150638 | J9: 0.72599769 | K9: =(J9*$K$2/9+I9)*31 -> 102.97357 | L9: =K9/D9/$K$1*1000 -> 10020.438 | M9: =L9*1000/31/24/3600*$K$1 -> 0.86047666 | O9: =Shahrdary!C38 -> 45.2492 | P9: =Shahrdary!J38 -> 73.086671 | Q9: =P9*3600*24*31/1000/1000 -> 195.75534 | R9: =Q9*1000/O9/$K$1 -> 18809.397 | S9: =R9*1000/31/24/3600*$K$1 -> 1.6152036 | U9: =O9-D9 -> 0.5694 | W9: 73.1793 | X9: 176.82755 | Y9: =X9*1000/W9/$K$1 -> 10505.914 | Z9: =Y9*1000/31/24/3600*$K$1 -> 0.90216558 | AA9: =W9-D9 -> 28.4995 | AB9: =W9-O9 -> 27.9301 | AC9: =X9-Q9 -> -18.927786 | AD9: =Z9*W9 -> 66.019846 | AE9: 73.1793 | AF9: 180.97724 | AG9: =AF9*1000/AE9/$K$1 -> 10752.461 | AH9: =AG9*1000/31/24/3600*$K$1 -> 0.92333707 | AJ9: =1/AK9^0.5 -> 1 | AK9: 1
B10: 6 | C10: 1874.0366 | D10: 78.9624 | E10: 59.7095 | F10: 19.3502 | G10: 29.6732 | H10: 89.3827 | I10: 4.2208298 | J10: 0.58966583 | K10: =(J10*$K$2/9+I10)*31 -> 151.15644 | L10: =K10/D10/$K$1*1000 -> 8322.9726 | M10: =L10*1000/31/24/3600*$K$1 -> 0.71471166 | O10: =Shahrdary!C39 -> 78.4996 | P10: =Shahrdary!J39 -> 103.37367 | Q10: =P10*3600*24*31/1000/1000 -> 276.87604 | R10: =Q10*1000/O10/$K$1 -> 15335.223 | S10: =R10*1000/31/24/3600*$K$1 -> 1.3168688 | U10: =O10-D10 -> -0.4628 | W10: 89.3827 | X10: 257.27224 | Y10: =X10*1000/W10/$K$1 -> 12514.446 | Z10: =Y10*1000/31/24/3600*$K$1 -> 1.0746425 | AA10: =W10-D10 -> 10.4203 | AB10: =W10-O10 -> 10.8831 | AC10: =X10-Q10 -> -19.603802 | AD10: =Z10*W10 -> 96.05445 | AE10: 89.3827 | AF10: 191.53171 | AG10: =AF10*1000/AE10/$K$1 -> 9316.6412 | AH10: =AG10*1000/31/24/3600*$K$1 -> 0.80004013
B11: 7 | C11: 4747.0846 | D11: 452.6981 | E11: 71.4255 | F11: 381.3246 | G11: 456.31418 | H11: 527.73968 | I11: 5.2853843 | J11: 9.0678754 | K11: =(J11*$K$2/9+I11)*31 -> 476.18484 | L11: =K11/D11/$K$1*1000 -> 4573.3986 | M11: =L11*1000/31/24/3600*$K$1 -> 0.39272763 | O11: =Shahrdary!C40 -> 452.325 | P11: =Shahrdary!J40 -> 244.2337 | Q11: =P11*3600*24*31/1000/1000 -> 654.15554 | R11: =Q11*1000/O11/$K$1 -> 6287.8562 | S11: =R11*1000/31/24/3600*$K$1 -> 0.53995181 | U11: =O11-D11 -> -0.3731 | W11: 527.73968 | X11: 859.21665 | Y11: =X11*1000/W11/$K$1 -> 7078.726 | Z11: =Y11*1000/31/24/3600*$K$1 -> 0.60786551 | AA11: =W11-D11 -> 75.04158 | AB11: =W11-O11 -> 75.41468 | AC11: =X11-Q11 -> 205.06111 | AD11: =Z11*W11 -> 320.79475 | AE11: 527.73968 | AF11: 1472.1948 | AG11: =AF11*1000/AE11/$K$1 -> 12128.796 | AH11: =AG11*1000/31/24/3600*$K$1 -> 1.041526
B12: 8 | C12: 1932.1425 | D12: 111.2728 | E12: 41.5834 | F12: 69.6894 | G12: 63.5709 | H12: 105.1543 | I12: 2.969788 | J12: 1.2632809 | K12: =(J12*$K$2/9+I12)*31 -> 135.57644 | L12: =K12/D12/$K$1*1000 -> 5297.4561 | M12: =L12*1000/31/24/3600*$K$1 -> 0.45490401 | O12: =Shahrdary!C41 -> 188.9336 | P12: =Shahrdary!J41 -> 171.85526 | Q12: =P12*3600*24*31/1000/1000 -> 460.29712 | R12: =Q12*1000/O12/$K$1 -> 10592.567 | S12: =R12*1000/31/24/3600*$K$1 -> 0.90960664 | U12: =O12-D12 -> 77.6608 | W12: 105.1543 | X12: 218.35234 | Y12: =X12*1000/W12/$K$1 -> 9028.2375 | Z12: =Y12*1000/31/24/3600*$K$1 -> 0.77527428 | AA12: =W12-D12 -> -6.1185 | AB12: =W12-O12 -> -83.7793 | AC12: =X12-Q12 -> -241.94478 | AD12: =Z12*W12 -> 81.523424 | AE12: 105.1543 | AF12: 222.25403 | AG12: =AF12*1000/AE12/$K$1 -> 9189.5609 | AH12: =AG12*1000/31/24/3600*$K$1 -> 0.78912747
B13: 9 | C13: 4476.4873 | D13: 386.3511 | E13: 104.7408 | F13: 281.6102 | G13: 219.5193 | H13: 324.2601 | I13: 7.7299888 | J13: 4.3622875 | K13: =(J13*$K$2/9+I13)*31 -> 389.88622 | L13: =K13/D13/$K$1*1000 -> 4387.6088 | M13: =L13*1000/31/24/3600*$K$1 -> 0.37677346 | O13: =Shahrdary!C42 -> 418.588 | P13: =Shahrdary!J42 -> 283.805 | Q13: =P13*3600*24*31/1000/1000 -> 760.14332 | R13: =Q13*1000/O13/$K$1 -> 7895.5225 | S13: =R13*1000/31/24/3600*$K$1 -> 0.67800559 | U13: =O13-D13 -> 32.2369 | W13: 324.2601 | X13: 638.50031 | Y13: =X13*1000/W13/$K$1 -> 8561.301 | Z13: =Y13*1000/31/24/3600*$K$1 -> 0.73517743 | AA13: =W13-D13 -> -62.091 | AB13: =W13-O13 -> -94.3279 | AC13: =X13-Q13 -> -121.64301 | AD13: =Z13*W13 -> 238.38871 | AE13: 324.2601 | AF13: 730.25004 | AG13: =AF13*1000/AE13/$K$1 -> 9791.5229 | AH13: =AG13*1000/31/24/3600*$K$1 -> 0.84081924
B14: 10 | C14: 2335.6471 | D14: 152.724 | E14: 85.8894 | F14: 66.8314 | G14: 103.9836 | H14: 189.873 | I14: 6.1535799 | J14: 2.0663621 | K14: =(J14*$K$2/9+I14)*31 -> 261.93567 | L14: =K14/D14/$K$1*1000 -> 7456.9206 | M14: =L14*1000/31/24/3600*$K$1 -> 0.6403419 | O14: =Shahrdary!C43 -> 157.2299 | P14: =Shahrdary!J43 -> 170.62454 | Q14: =P14*3600*24*31/1000/1000 -> 457.00076 | R14: =Q14*1000/O14/$K$1 -> 12637.29 | S14: =R14*1000/31/24/3600*$K$1 -> 1.0851914 | U14: =O14-D14 -> 4.5059 | W14: 189.873 | X14: 448.82586 | Y14: =X14*1000/W14/$K$1 -> 10277.484 | Z14: =Y14*1000/31/24/3600*$K$1 -> 0.8825498 | AA14: =W14-D14 -> 37.149 | AB14: =W14-O14 -> 32.6431 | AC14: =X14-Q14 -> -8.1748967 | AD14: =Z14*W14 -> 167.57238 | AE14: 189.873 | AF14: 488.61359 | AG14: =AF14*1000/AE14/$K$1 -> 11188.568 | AH14: =AG14*1000/31/24/3600*$K$1 -> 0.9607865
B15: 11 | C15: 1536.0067 | D15: 106.3791 | E15: 88.1413 | F15: 18.3808 | G15: 33.4647 | H15: 121.606 | I15: 6.1143662 | J15: 0.66501052 | K15: =(J15*$K$2/9+I15)*31 -> 212.45127 | L15: =K15/D15/$K$1*1000 -> 8683.1076 | M15: =L15*1000/31/24/3600*$K$1 -> 0.74563723 | O15: =Shahrdary!C44 -> 109.6369 | P15: =Shahrdary!J44 -> 162.44113 | Q15: =P15*3600*24*31/1000/1000 -> 435.08232 | R15: =Q15*1000/O15/$K$1 -> 17253.883 | S15: =R15*1000/31/24/3600*$K$1 -> 1.4816283 | U15: =O15-D15 -> 3.2578 | W15: 121.606 | X15: 364.20895 | Y15: =X15*1000/W15/$K$1 -> 13021.703 | Z15: =Y15*1000/31/24/3600*$K$1 -> 1.1182018 | AA15: =W15-D15 -> 15.2269 | AB15: =W15-O15 -> 11.9691 | AC15: =X15-Q15 -> -70.873369 | AD15: =Z15*W15 -> 135.98005 | AE15: 121.606 | AF15: 283.44533 | AG15: =AF15*1000/AE15/$K$1 -> 10134.13 | AH15: =AG15*1000/31/24/3600*$K$1 -> 0.87023965
B16: 12 | C16: 6506.3395 | D16: 84.6394 | E16: 30.6439 | F16: 53.9955 | G16: 93.1149 | H16: 123.7588 | I16: 2.365272 | J16: 1.8503793 | K16: =(J16*$K$2/9+I16)*31 -> 137.05872 | L16: =K16/D16/$K$1*1000 -> 7040.5447 | M16: =L16*1000/31/24/3600*$K$1 -> 0.6045868 | O16: =Shahrdary!C45 -> 85.5213 | P16: =Shahrdary!J45 -> 89.606466 | Q16: =P16*3600*24*31/1000/1000 -> 240.00196 | R16: =Q16*1000/O16/$K$1 -> 12201.484 | S16: =R16*1000/31/24/3600*$K$1 -> 1.0477678 | U16: =O16-D16 -> 0.8819 | W16: 123.7588 | X16: 237.15974 | Y16: =X16*1000/W16/$K$1 -> 8331.7656 | Z16: =Y16*1000/31/24/3600*$K$1 -> 0.71546673 | AA16: =W16-D16 -> 39.1194 | AB16: =W16-O16 -> 38.2375 | AC16: =X16-Q16 -> -2.8422159 | AD16: =Z16*W16 -> 88.545304 | AE16: 123.7588 | AF16: 294.33443 | AG16: =AF16*1000/AE16/$K$1 -> 10340.395 | AH16: =AG16*1000/31/24/3600*$K$1 -> 0.88795212
B17: 13 | C17: 356.46676 | D17: 7.2237 | E17: 7.0732 | F17: 0.1505 | G17: 2.0961 | H17: 9.1693 | I17: 0.51769708 | J17: 0.041653699 | K17: =(J17*$K$2/9+I17)*31 -> 17.483348 | L17: =K17/D17/$K$1*1000 -> 10522.939 | M17: =L17*1000/31/24/3600*$K$1 -> 0.90362756 | O17: =Shahrdary!C46 -> 7.2237 | P17: =Shahrdary!J46 -> 13.139682 | Q17: =P17*3600*24*31/1000/1000 -> 35.193325 | R17: =Q17*1000/O17/$K$1 -> 21182.283 | S17: =R17*1000/31/24/3600*$K$1 -> 1.8189684 | U17: =O17-D17 -> 0 | W17: 9.1693 | X17: 29.754772 | Y17: =X17*1000/W17/$K$1 -> 14108.882 | Z17: =Y17*1000/31/24/3600*$K$1 -> 1.2115602 | AA17: =W17-D17 -> 1.9456 | AB17: =W17-O17 -> 1.9456 | AC17: =X17-Q17 -> -5.438553 | AD17: =Z17*W17 -> 11.109159 | AE17: 9.1693 | AF17: 23.942189 | AG17: =AF17*1000/AE17/$K$1 -> 11352.718 | AH17: =AG17*1000/31/24/3600*$K$1 -> 0.97488241
D18: 0 | E18: 0 | F18: 0 | G18: 0 | H18: 0 | I18: 0 | J18: 0 | K18: =(J18*$K$2/9+I18)*31 -> 0 | M18: =L18*1000/31/24/3600*$K$1 -> 0 | O18: =Shahrdary!C47 -> 0 | P18: =Shahrdary!J47 -> 0 | Q18: =P18*3600*24*31/1000/1000 -> 0 | S18: =R18*1000/31/24/3600*$K$1 -> 0 | U18: =O18-D18 -> 0 | Z18: =Y18*1000/31/24/3600*$K$1 -> 0 | AA18: =W18-D18 -> 0 | AB18: =W18-O18 -> 0 | AC18: =X18-Q18 -> 0 | AD18: =Z18*W18 -> 0 | AH18: =AG18*1000/31/24/3600*$K$1 -> 0
D19: 0 | E19: 0 | F19: 0 | G19: 0 | H19: 0 | I19: 0 | J19: 0 | K19: =(J19*$K$2/9+I19)*31 -> 0 | M19: =L19*1000/31/24/3600*$K$1 -> 0 | O19: =Shahrdary!C48 -> 0 | P19: =Shahrdary!J48 -> 0 | Q19: =P19*3600*24*31/1000/1000 -> 0 | S19: =R19*1000/31/24/3600*$K$1 -> 0 | U19: =O19-D19 -> 0 | W19: 0 | Z19: =Y19*1000/31/24/3600*$K$1 -> 0 | AA19: =W19-D19 -> 0 | AB19: =W19-O19 -> 0 | AC19: =X19-Q19 -> 0 | AD19: =Z19*W19 -> 0 | AE19: 0 | AH19: =AG19*1000/31/24/3600*$K$1 -> 0
B20: 16 | D20: 33.664 | E20: 19.8417 | F20: 13.8223 | G20: 25.6862 | H20: 45.5279 | I20: 1.1434534 | J20: 0.51043617 | K20: =(J20*$K$2/9+I20)*31 -> 53.028744 | L20: =K20/D20/$K$1*1000 -> 6848.8521 | M20: =L20*1000/31/24/3600*$K$1 -> 0.58812574 | O20: =Shahrdary!C49 -> 33.2012 | P20: =Shahrdary!J49 -> 37.895949 | Q20: =P20*3600*24*31/1000/1000 -> 101.50051 | R20: =Q20*1000/O20/$K$1 -> 13291.886 | S20: =R20*1000/31/24/3600*$K$1 -> 1.141403 | U20: =O20-D20 -> -0.4628 | W20: 45.5279 | X20: 97.316458 | Y20: =X20*1000/W20/$K$1 -> 9293.5328 | Z20: =Y20*1000/31/24/3600*$K$1 -> 0.79805576 | AA20: =W20-D20 -> 11.8639 | AB20: =W20-O20 -> 12.3267 | AC20: =X20-Q20 -> -4.1840534 | AD20: =Z20*W20 -> 36.333803 | AE20: 45.5279 | AF20: 74.605931 | AG20: =AF20*1000/AE20/$K$1 -> 7124.7216 | AH20: =AG20*1000/31/24/3600*$K$1 -> 0.61181525
C21: =SUM(C5:C17) -> 35186.682 | D21: =SUM(D5:D20) -> 1781.2624 | E21: =SUM(E5:E20) -> 774.0852 | F21: =SUM(F5:F20) -> 1007.7227 | G21: =SUM(G5:G20) -> 1210.9334 | H21: =SUM(H5:H20) -> 1985.0186 | I21: =SUM(I5:I20) -> 55.07226 | J21: =SUM(J5:J20) -> 24.063668 | K21: =SUM(K5:K20) -> 2536.0997 | L21: =ROUND(SUMPRODUCT(L5:L20,D5:D20)/D21,-1) -> 6190 | M21: =SUMPRODUCT(M5:M20,D5:D20)/D21 -> 0.53157309 | O21: =SUM(O5:O20) -> 1903.1727 | P21: =SUM(P5:P20) -> 1776.7579 | Q21: =SUM(Q5:Q20) -> 4758.8684 | R21: =ROUND(SUMPRODUCT(R5:R20,O5:O20)/O21,-1) -> 10870 | S21: =SUMPRODUCT(S5:S20,P5:P20)/P21 -> 1.064023 | W21: =SUM(W5:W17,W20) -> 1985.0186 | X21: =SUM(X5:X17,X20) -> 4352.75 | Y21: =ROUND(SUMPRODUCT(Y5:Y20,W5:W20)/W21,-1) -> 9530 | Z21: =SUMPRODUCT(Z5:Z20,W5:W20)/W21 -> 0.81869796 | AC21: =SUM(AC5:AC17,AC20) -> -406.11842 | AE21: =SUM(AE5:AE17,AE20) -> 1985.0186 | AF21: =SUM(AF5:AF17,AF20) -> 4877.8356 | AG21: =ROUND(SUMPRODUCT(AG5:AG20,AE5:AE20)/AE21,-1) -> 10680 | AH21: =SUMPRODUCT(AH5:AH20,AE5:AE20)/AE21 -> 0.91746002
C22: حجم نیاز سالانه | E22: میلیون مترمکعب | K22: =K21/K1/1000 -> 11.026521 | Q22: =Q21/K1/1000 -> 20.690732 | S22: =+S21*P21 -> 1890.5112 | X22: =X21/X1/1000 -> 18.653792 | Z22: =+Z21*W21 -> 1625.1307 | AF22: =AF21/AE1/1000 -> 22.029865
B24: ترتیب بانک | E24: آبدهی واحد | G24: عبارات موجود در بانک | I24: دسته‌بندی تکمیلی/ شناسه‌سازی/ ضرائب
E25: Q_HM | G25: شکل لکه | I25: شناسه | J25: شکل لکه | N25: ضریب
E26: l/s/ha | G26: 0 | I26: 0 | J26: 0 | N26: خُرداقلیم
B27: آیلند ها | C27: =MATCH(B27,$C$21:$C$33,0) -> #N/A | E27: 1.067 | G27: میادین | H27: 1 | I27: 1 | J27: میدان | N27: 1.2
B28: آیلند های بزرگراه | C28: =MATCH(B28,$C$21:$C$33,0) -> #N/A | E28: 1.067 | G28: لچکی ها | H28: 2 | I28: 2 | J28: لچکی‌ | N28: 1.2
B29: پارک های بالای 10 هکتار | C29: =MATCH(B29,$C$21:$C$33,0) -> #N/A | E29: 1.067 | G29: آیلند های بزرگراه | H29: 3 | I29: 3 | J29: وسط بزرگراه | N29: 1.15
B30: پارک های بین 6 تا 10 هکتار | C30: =MATCH(B30,$C$21:$C$33,0) -> #N/A | E30: 1.067 | G30: آیلند ها | H30: 4 | I30: 4 | J30: وسط بلوار | N30: 1.1
B31: پارک های زیر 6 هکتار | C31: =MATCH(B31,$C$21:$C$33,0) -> #N/A | E31: 1.067 | G31: حاشیه های بزرگراه | H31: 5 | I31: 5 | J31: حاشیه‌ بزرگراه | N31: 1.1
B32: جنگل کاری داخل محدوده | C32: =MATCH(B32,$C$21:$C$33,0) -> #N/A | E32: 1.067 | G32: حاشیه معابر | H32: 6 | I32: 6 | J32: حاشیه معابر/ بلوار | N32: 1.05
B33: حاشیه معابر | C33: =MATCH(B33,$C$21:$C$33,0) -> #N/A | E33: 0.667 | G33: پارک های زیر 6 هکتار | H33: 8 | I33: 7 | J33: بوستان خطی | N33: 1.05
B34: حاشیه های بزرگراه | C34: =MATCH(B34,$C$21:$C$33,0) -> #N/A | E34: 0.667 | G34: پارک های بین 6 تا 10 هکتار | H34: 9 | I34: 8 | J34: بوستان؛ کمتراز 6 هـ | N34: 1
B35: کمربند سبز حفاظتی | C35: =MATCH(B35,$C$21:$C$33,0) -> #N/A | E35: 0.667 | G35: پارک های بالای 10 هکتار | H35: 10 | I35: 9 | J35: بوستان؛ 6 تا 10 هـ | N35: 0.9
B36: کمربندی | C36: =MATCH(B36,$C$21:$C$33,0) -> #N/A | E36: 0.667 | G36: جنگل کاری داخل محدوده | H36: 11 | I36: 10 | J36: بوستان؛ بیش‌از 10 هـ | N36: 0.8
B37: لچکی ها | C37: =MATCH(B37,$C$21:$C$33,0) -> #N/A | E37: 0.334 | G37: کمربند سبز حفاظتی | H37: 12 | I37: 11 | J37: جنگل‌کاری | N37: 1
B38: میادین | C38: =MATCH(B38,$C$21:$C$33,0) -> #N/A | E38: 0.23 | G38: کمربندی | H38: 12 | I38: 12 | J38: کمربندی | N38: 1.05
G39: 0 | H39: 0 | I39: 13 | J39: - | N39: -
B41: منطقه | C41: نیاز آبی تیرماه | D41: نیاز واحد (مترمکعب در هکتار)
C42: هزار متر مکعب
...

Sheet 16
B2: از برآورد مهندسی | N2: 0.23 | O2: 10 | R2: از روش دفتر محیط زیست- نرم‌افزاری
B3: شناسهء پیمان/ | D3: فضای سبز (نگهداری) | E3: سطوح آبیاری لکه‌ها | F3: سطح نگهداری تک‌درختان | G3: سطح تبخیرتعرق تک‌درختان | H3: سطح برآورد تبخیرتعرق | I3: نیاز آبیاری لکه‌ها | J3: نیازآبیاری تک‌درختان | K3: نیاز آبیاری لکه‌ها | L3: نیازآبیاری تک‌درختان | R3: مساحت | S3: نیاز آبی سالانه | T3: نیاز آبی تیر ماه | Z3: 940924
B4: نام لکه در بانک نگهداری | C4: نشانی/ توضیحات | D4: مترمربع | E4: مترمربع | F4: مترمربع | G4: مترمربع | H4: مترمربع | I4: مترمکعب درروز | K4: لیتردرثانیه | L4: لیتردرثانیه | M4: هزار مترمکعب | N4: مترمکعب در هکتار | O4: لیتردرثانیه درهکتار | R4: مترمربع | S4: مترمکعب | T4: مترمکعب | U4: مترمکعب در هکتار | W4: لیتردرثانیه درهکتار | Z4: 34812
B5: پارک ریحانه | D5: 81110 | E5: 22687 | F5: 58423 | G5: 82094 | H5: 104781 | I5: 130.74246 | J5: 163.1372 | K5: 1.5132229 | L5: 1.888162 | M5: =(J5*$O$2/9+I5)*31/1000*P5 -> 17.023048 | N5: =M5/(D5/10000)/$N$2*1000 -> 9125.0465 | O5: =N5*1000/31/24/3600*$N$2 -> 0.78358747 | P5: 1.76 | R5: 82094 | S5: 300725.54 | T5: 72675.713 | U5: =S5/R5*10000 -> 36631.854 | V5: =T5/S5 -> 0.24166791 | W5: =U5*1000/31/24/3600*$N$2 -> 3.1456565 | Z5: =Z3-Z4 -> 906112
B6: پاغ گیاهشناسی | D6: 174768 | E6: 94968 | F6: 79800 | G6: 174768 | H6: 269736 | I6: 547.28919 | J6: 347.29897 | K6: 6.3343656 | L6: 4.019664 | M6: =(J6*$O$2/9+I6)*31/1000*P6 -> 50.914133 | N6: =M6/(D6/10000)/$N$2*1000 -> 12666.266 | O6: =N6*1000/31/24/3600*$N$2 -> 1.0876797 | P6: =P5 -> 1.76 | R6: 174768 | S6: 460264.8 | T6: 109653.17 | U6: =S6/R6*10000 -> 26335.759 | V6: =T6/S6 -> 0.2382393 | W6: =U6*1000/31/24/3600*$N$2 -> 2.2615086 | Z6: 156533
B7: پارک دانش | D7: 13428 | E7: 13428 | F7: 0 | G7: 0 | H7: 13428 | I7: 77.383953 | J7: 0 | K7: 0.8956476 | L7: 0 | M7: =(J7*$O$2/9+I7)*31/1000*P7 -> 4.2220685 | N7: =M7/(D7/10000)/$N$2*1000 -> 13670.554 | O7: =N7*1000/31/24/3600*$N$2 -> 1.17392 | P7: =P6 -> 1.76 | R7: 13428 | S7: 18725.314 | T7: 4179.2022 | U7: =S7/R7*10000 -> 13944.976 | V7: =T7/S7 -> 0.22318463 | W7: =U7*1000/31/24/3600*$N$2 -> 1.1974853 | Z7: =Z5-Z6 -> 749579
B8: باغ گلها | D8: 13334 | E8: 13334 | F8: 0 | G8: 0 | H8: 13334 | I8: 76.842242 | J8: 0 | K8: 0.8893778 | L8: 0 | M8: =(J8*$O$2/9+I8)*31/1000*P8 -> 4.1925127 | N8: =M8/(D8/10000)/$N$2*1000 -> 13670.554 | O8: =N8*1000/31/24/3600*$N$2 -> 1.17392 | P8: =P7 -> 1.76 | R8: 13334 | S8: 20565.599 | T8: 4675.8371 | U8: =S8/R8*10000 -> 15423.428 | V8: =T8/S8 -> 0.22736206 | W8: =U8*1000/31/24/3600*$N$2 -> 1.3244431
B9: پارک مینیاتوری | D9: 54000 | E9: 54000 | F9: 0 | G9: 0 | H9: 54000 | I9: 311.19552 | J9: 0 | K9: 3.6018 | L9: 0 | M9: =(J9*$O$2/9+I9)*31/1000*P9 -> 16.978828 | N9: =M9/(D9/10000)/$N$2*1000 -> 13670.554 | O9: =N9*1000/31/24/3600*$N$2 -> 1.17392 | P9: =P8 -> 1.76 | R9: 54000 | S9: 84457.242 | T9: 18645.624 | U9: =S9/R9*10000 -> 15640.23 | V9: =T9/S9 -> 0.22076998 | W9: =U9*1000/31/24/3600*$N$2 -> 1.3430604
D10: =SUM(D5:D9) -> 336640 | K10: =SUM(K5:K9) -> 13.234414 | L10: =SUM(L5:L9) -> 5.907826 | M10: =SUM(M5:M9) -> 93.33059 | N10: =SUMPRODUCT(N5:N9,D5:D9)/D10 -> 12053.98 | O10: =N10*1000/31/24/3600*$N$2 -> 1.0351013 | R10: =SUM(R5:R9) -> 337624 | S10: =SUM(S5:S9) -> 884738.5 | T10: =SUM(T5:T9) -> 209829.54 | U10: =S10/R10*10000 -> 26204.846 | V10: =T10/S10 -> 0.23716561 | W10: =U10*1000/31/24/3600*$N$2 -> 2.2502668
H12: =H5/D5 -> 1.2918382
H13: =H6/D6 -> 1.5433947
H14: =H7/D7 -> 1 | M14: با اصلاح متر و سطح باغها
B15: پارک ریحانه | D15: 81110 | E15: 22687 | F15: 58423 | G15: 82094 | H15: 104781 | I15: 130.74246 | J15: 163.1372 | K15: 1.5132229 | L15: 1.888162
B16: پاغ گیاهشناسی | D16: 174768 | E16: 94968 | F16: 79800 | G16: 174768 | H16: 269736 | I16: 547.28919 | J16: 347.29897 | K16: 6.3343656 | L16: 4.019664
B17: پارک دانش | D17: 13428 | E17: 13428 | F17: 0 | G17: 0 | H17: 13428 | I17: 77.383953 | J17: 0 | K17: 0.8956476 | L17: 0
B18: باغ گلها | D18: 13334 | E18: 13334 | F18: 0 | G18: 0 | H18: 13334 | I18: 76.842242 | J18: 0 | K18: 0.8893778 | L18: 0
B19: پارک مینیاتوری | D19: 54000 | E19: 54000 | F19: 0 | G19: 0 | H19: 54000 | I19: 311.19552 | J19: 0 | K19: 3.6018 | L19: 0
D20: =SUM(D15:D19) -> 336640 | K20: =SUM(K15:K19) -> 13.234414 | L20: =SUM(L15:L19) -> 5.907826 | M20: =SUM(M15:M19) -> 0 | N20: =SUMPRODUCT(N15:N19,D15:D19)/D20 -> 0 | O20: =N20*1000/31/24/3600*$N$2 -> 0 | R20: =SUM(R15:R19) -> 0 | S20: =SUM(S15:S19) -> 0 | T20: =SUM(T15:T19) -> 0 | U20: =S20/R20*10000 -> #DIV/0! | V20: =T20/S20 -> #DIV/0! | W20: =U20*1000/31/24/3600*$N$2 -> #DIV/0!

Sheet Abs (2)
B2: وضعیت مناطق و پیمان‌‌ها و تحلیل تعداد و پراکنش لکه در هر پیمان | AD2: نیاز آبیاری؛ لیتردرثانیه
B3: منطقه | C3: محدوده | D3: پيمان | E3: نام پیمان | F3: سطح کاربری فضای سبز؛ مترمربع | X3: ترتیب و نام قبلی پیمان | AA3: توسعه ویژه؛ مترمربع | AF3: 0.15
B4: District | C4: Region | D4: Peyman | E4: Peyman | F4: وضعِ موجود | G4: درحال توسعه‌ | H4: طرح تفصیلی | I4: پهنه‌های ‌توسعه‌نیافته | J4: طرح تفصیلی اولیه | O4: =IF(B4="",O3,B4) -> District | P4: =IF(C4="",P3,C4) -> Region | Q4: =IF(D4="",Q3,D4) -> Peyman | R4: Reg.Pey | S4: Code | T4: Count | AA4: معابر | AB4: بوستان‌ها | AC4: جنگل‌کاری | AD4: کمربندی | AE4: جمع
A5: =+S5 -> 010101 | B5: 01 | C5: 01 | D5: 01 | E5: الف ناحیه 1 منطقه 1 | F5: 102205 | G5: 0 | H5: 0 | I5: 0 | J5: 0 | O5: =IF(B5="",O4,B5) -> 01 | P5: =IF(C5="",P4,C5) -> 01 | Q5: =IF(D5="",Q4,D5) -> 01 | R5: =CONCATENATE(P5,Q5) -> 0101 | S5: =CONCATENATE(O5,P5,Q5) -> 010101 | U5: =VALUE(S5) -> 10101
A6: =+S6 -> 010201 | C6: 02 | D6: 01 | E6: الف ناحیه 2 منطقه 1 - 9808 | F6: 160580 | G6: 0 | H6: 59659 | I6: 0 | J6: 59659 | O6: =IF(B6="",O5,B6) -> 01 | P6: =IF(C6="",P5,C6) -> 02 | Q6: =IF(D6="",Q5,D6) -> 01 | R6: =CONCATENATE(P6,Q6) -> 0201 | S6: =CONCATENATE(O6,P6,Q6) -> 010201 | U6: =VALUE(S6) -> 10201
A7: =+S7 -> 010202 | D7: 02 | E7: ب ناحیه 2 منطقه 1 - 9808 | F7: 88067 | G7: 0 | H7: 5524 | I7: 0 | J7: 5524 | O7: =IF(B7="",O6,B7) -> 01 | P7: =IF(C7="",P6,C7) -> 02 | Q7: =IF(D7="",Q6,D7) -> 02 | R7: =CONCATENATE(P7,Q7) -> 0202 | S7: =CONCATENATE(O7,P7,Q7) -> 010202 | U7: =VALUE(S7) -> 10202
A8: =+S8 -> 010301 | C8: 03 | D8: 01 | E8: ناحیه 3 منطقه 1 - 9711 | F8: 73378 | G8: 0 | H8: 37692 | I8: 0 | J8: 37692 | O8: =IF(B8="",O7,B8) -> 01 | P8: =IF(C8="",P7,C8) -> 03 | Q8: =IF(D8="",Q7,D8) -> 01 | R8: =CONCATENATE(P8,Q8) -> 0301 | S8: =CONCATENATE(O8,P8,Q8) -> 010301 | U8: =VALUE(S8) -> 10301
A9: =+S9 -> 020101 | B9: 02 | C9: 01 | D9: 01 | E9: الف ناحیه 1 منطقه 2 - 9809 | H9: 47601 | J9: 314971 | O9: =IF(B9="",O8,B9) -> 02 | P9: =IF(C9="",P8,C9) -> 01 | Q9: =IF(D9="",Q8,D9) -> 01 | R9: =CONCATENATE(P9,Q9) -> 0101 | S9: =CONCATENATE(O9,P9,Q9) -> 020101 | U9: =VALUE(S9) -> 20101
A10: =+S10 -> 020102 | D10: 02 | E10: ب ناحیه 1 منطقه 2 | O10: =IF(B10="",O9,B10) -> 02 | P10: =IF(C10="",P9,C10) -> 01 | Q10: =IF(D10="",Q9,D10) -> 02 | R10: =CONCATENATE(P10,Q10) -> 0102 | S10: =CONCATENATE(O10,P10,Q10) -> 020102 | U10: =VALUE(S10) -> 20102
A11: =+S11 -> 020103 | D11: 03 | E11: ج ناحیه 1 منطقه 2 | O11: =IF(B11="",O10,B11) -> 02 | P11: =IF(C11="",P10,C11) -> 01 | Q11: =IF(D11="",Q10,D11) -> 03 | R11: =CONCATENATE(P11,Q11) -> 0103 | S11: =CONCATENATE(O11,P11,Q11) -> 020103 | U11: =VALUE(S11) -> 20103 | AA11: =+Z12-AA12-AA13 -> 561.66282
A12: =+S12 -> 02201 | C12: 2 | D12: 01 | E12: صدمتری ناحیه 2 منطقه 2 - 9810 | G12: 331320 | H12: 878273 | J12: 916130 | O12: =IF(B12="",O11,B12) -> 02 | P12: =IF(C12="",P11,C12) -> 2 | Q12: =IF(D12="",Q11,D12) -> 01 | R12: =CONCATENATE(P12,Q12) -> 201 | S12: =CONCATENATE(O12,P12,Q12) -> 02201 | U12: =VALUE(S12) -> 2201 | W12: 01 | X12: بوستان پردیس ب ناحیه 2 منطقه 2 - 9808 | Z12: =11016628.2027/10000 -> 1101.6628 | AA12: 270 | AB12: =1.8/100*AA12*10000 -> 48600 | AC12: =2.2/100*AA12*10000 -> 59400 | AD12: =+AB12/10000*#REF! -> #REF! | AE12: =+AC12/10000*#REF! -> #REF! | AF12: =SUM(AD12:AE12)*(1+$AF$3) -> #REF! | AG12: =+AF12*1.5 -> #REF!
A13: =+S13 -> 02202 | D13: 02 | E13: بوستان پردیس ب ناحیه 2 منطقه 2 - 9808 | H13: 0 | J13: 148541 | O13: =IF(B13="",O12,B13) -> 02 | P13: =IF(C13="",P12,C13) -> 2 | Q13: =IF(D13="",Q12,D13) -> 02 | R13: =CONCATENATE(P13,Q13) -> 202 | S13: =CONCATENATE(O13,P13,Q13) -> 02202 | U13: =VALUE(S13) -> 2202 | W13: 02 | X13: صدمتری ناحیه 2 منطقه 2 - 9810 | AA13: 270 | AB13: =1.8/100*AA13*10000 -> 48600 | AC13: =2.2/100*AA13*10000 -> 59400 | AD13: =+AB13/10000*#REF! -> #REF! | AE13: =+AC13/10000*#REF! -> #REF! | AF13: =SUM(AD13:AE13)*(1+$AF$3) -> #REF! | AG13: =+AF13*1.5 -> #REF!
A14: =+S14 -> 020301 | C14: 03 | D14: 01 | E14: ناحیه 3 منطقه 2 | H14: 197603 | J14: 454117 | O14: =IF(B14="",O13,B14) -> 02 | P14: =IF(C14="",P13,C14) -> 03 | Q14: =IF(D14="",Q13,D14) -> 01 | R14: =CONCATENATE(P14,Q14) -> 0301 | S14: =CONCATENATE(O14,P14,Q14) -> 020301 | U14: =VALUE(S14) -> 20301 | Z14: =7160777.21330999/10000 -> 716.07772 | AA14: =+Z14 -> 716.07772 | AB14: =1.8/100*AA14*10000 -> 128893.99 | AC14: =2.2/100*AA14*10000 -> 157537.1 | AD14: =+AB14/10000*#REF! -> #REF! | AE14: =+AC14/10000*#REF! -> #REF! | AF14: =SUM(AD14:AE14)*(1+$AF$3) -> #REF! | AG14: =+AF14*1.5 -> #REF!
A15: =+S15 -> 020401 | C15: 04 | D15: 01 | E15: الف ناحیه 4 منطقه 2 | H15: 6288 | J15: 123129 | O15: =IF(B15="",O14,B15) -> 02 | P15: =IF(C15="",P14,C15) -> 04 | Q15: =IF(D15="",Q14,D15) -> 01 | R15: =CONCATENATE(P15,Q15) -> 0401 | S15: =CONCATENATE(O15,P15,Q15) -> 020401 | U15: =VALUE(S15) -> 20401
A16: =+S16 -> 020402 | D16: 02 | E16: ب ناحیه 4 منطقه 2 - 9803 | O16: =IF(B16="",O15,B16) -> 02 | P16: =IF(C16="",P15,C16) -> 04 | Q16: =IF(D16="",Q15,D16) -> 02 | R16: =CONCATENATE(P16,Q16) -> 0402 | S16: =CONCATENATE(O16,P16,Q16) -> 020402 | U16: =VALUE(S16) -> 20402
A17: =+S17 -> 030101 | B17: 03 | C17: 01 | D17: 01 | E17: ناحیه 1 منطقه 3 - 9811 | F17: 106996 | G17: 0 | H17: 54363 | I17: 0 | J17: 83755 | O17: =IF(B17="",O16,B17) -> 03 | P17: =IF(C17="",P16,C17) -> 01 | Q17: =IF(D17="",Q16,D17) -> 01 | R17: =CONCATENATE(P17,Q17) -> 0101 | S17: =CONCATENATE(O17,P17,Q17) -> 030101 | U17: =VALUE(S17) -> 30101 | X17: ناحیه 1 منطقه 3
A18: =+S18 -> 030201 | C18: 02 | D18: 01 | E18: ناحیه 2 منطقه 3 - 9810 | F18: 186106 | G18: 4429229.2 | H18: 342952 | I18: 0 | J18: 489416 | O18: =IF(B18="",O17,B18) -> 03 | P18: =IF(C18="",P17,C18) -> 02 | Q18: =IF(D18="",Q17,D18) -> 01 | R18: =CONCATENATE(P18,Q18) -> 0201 | S18: =CONCATENATE(O18,P18,Q18) -> 030201 | U18: =VALUE(S18) -> 30201
A19: =+S19 -> 030301 | C19: 03 | D19: 01 | E19: ناحیه 3 منطقه 3 - 9808 | F19: 269617 | G19: 7367096.3 | H19: 1081436 | I19: 0 | J19: 1371712 | O19: =IF(B19="",O18,B19) -> 03 | P19: =IF(C19="",P18,C19) -> 03 | Q19: =IF(D19="",Q18,D19) -> 01 | R19: =CONCATENATE(P19,Q19) -> 0301 | S19: =CONCATENATE(O19,P19,Q19) -> 030301 | U19: =VALUE(S19) -> 30301
A20: =+S20 -> 030302 | D20: 02 | E20: پارک بهار ناحیه 3 منطقه 3 -9706 | F20: 429266 | G20: 0 | H20: 0 | I20: 0 | J20: 783669 | O20: =IF(B20="",O19,B20) -> 03 | P20: =IF(C20="",P19,C20) -> 03 | Q20: =IF(D20="",Q19,D20) -> 02 | R20: =CONCATENATE(P20,Q20) -> 0302 | S20: =CONCATENATE(O20,P20,Q20) -> 030302 | U20: =VALUE(S20) -> 30302
A21: =+S21 -> 030401 | C21: 04 | D21: 01 | E21: ناحیه 4 منطقه 3 - 9810 | F21: 44674 | G21: 0 | H21: 0 | I21: 0 | J21: 0 | O21: =IF(B21="",O20,B21) -> 03 | P21: =IF(C21="",P20,C21) -> 04 | Q21: =IF(D21="",Q20,D21) -> 01 | R21: =CONCATENATE(P21,Q21) -> 0401 | S21: =CONCATENATE(O21,P21,Q21) -> 030401 | U21: =VALUE(S21) -> 30401
A22: =+S22 -> 040101 | B22: 04 | C22: 01 | D22: 01 | E22: ناحیه 1 منطقه 4 - 9708 | F22: 131294 | G22: 0 | H22: 122966 | I22: 0 | J22: 288603 | O22: =IF(B22="",O21,B22) -> 04 | P22: =IF(C22="",P21,C22) -> 01 | Q22: =IF(D22="",Q21,D22) -> 01 | R22: =CONCATENATE(P22,Q22) -> 0101 | S22: =CONCATENATE(O22,P22,Q22) -> 040101 | U22: =VALUE(S22) -> 40101
A23: =+S23 -> 040201 | C23: 02 | D23: 01 | E23: ناحیه 2 منطقه 4 - 9812 | F23: 192067 | G23: 0 | H23: 23205 | I23: 0 | J23: 153118 | O23: =IF(B23="",O22,B23) -> 04 | P23: =IF(C23="",P22,C23) -> 02 | Q23: =IF(D23="",Q22,D23) -> 01 | R23: =CONCATENATE(P23,Q23) -> 0201 | S23: =CONCATENATE(O23,P23,Q23) -> 040201 | U23: =VALUE(S23) -> 40201 | X23: ناحیه 2 منطقه 4 - 9712
A24: =+S24 -> 040301 | C24: 03 | D24: 01 | E24: ناحیه 3 منطقه 4 - 9807 | F24: 193349 | G24: 133752 | H24: 542349 | I24: 0 | J24: 733675 | O24: =IF(B24="",O23,B24) -> 04 | P24: =IF(C24="",P23,C24) -> 03 | Q24: =IF(D24="",Q23,D24) -> 01 | R24: =CONCATENATE(P24,Q24) -> 0301 | S24: =CONCATENATE(O24,P24,Q24) -> 040301 | U24: =VALUE(S24) -> 40301
A25: =+S25 -> 050101 | B25: 05 | C25: 01 | D25: 01 | E25: بوستان وحدت الف ناحیه 1 منطقه 5 - 9710 | F25: 78472 | G25: 0 | H25: 0 | I25: 0 | J25: 142790 | O25: =IF(B25="",O24,B25) -> 05 | P25: =IF(C25="",P24,C25) -> 01 | Q25: =IF(D25="",Q24,D25) -> 01 | R25: =CONCATENATE(P25,Q25) -> 0101 | S25: =CONCATENATE(O25,P25,Q25) -> 050101 | U25: =VALUE(S25) -> 50101 | W25: 01 | X25: ب ناحیه 1 منطقه 5 - 9708
A26: =+S26 -> 050102 | D26: 02 | E26: ب ناحیه 1 منطقه 5 - 9708 | F26: 194978 | G26: 446820 | H26: 205363 | I26: 143954 | J26: 405760 | O26: =IF(B26="",O25,B26) -> 05 | P26: =IF(C26="",P25,C26) -> 01 | Q26: =IF(D26="",Q25,D26) -> 02 | R26: =CONCATENATE(P26,Q26) -> 0102 | S26: =CONCATENATE(O26,P26,Q26) -> 050102 | U26: =VALUE(S26) -> 50102 | W26: 02 | X26: بوستان وحدت الف ناحیه 1 منطقه 5 - 9710
A27: =+S27 -> 050201 | C27: 02 | D27: 01 | E27: ناحیه 2 منطقه 5 - 9810 | F27: 179042 | G27: 205705 | H27: 266373 | I27: 3083985 | J27: 409550 | O27: =IF(B27="",O26,B27) -> 05 | P27: =IF(C27="",P26,C27) -> 02 | Q27: =IF(D27="",Q26,D27) -> 01 | R27: =CONCATENATE(P27,Q27) -> 0201 | S27: =CONCATENATE(O27,P27,Q27) -> 050201 | U27: =VALUE(S27) -> 50201 | X27: الف ناحیه 2 منطقه 5
A28: =+S28 -> 060101 | B28: 06 | C28: 01 | D28: 01 | E28: الف ناحیه 1 منطقه 6 - 9711 | F28: 99484 | G28: 6000 | H28: 200422 | I28: 0 | J28: 297040 | O28: =IF(B28="",O27,B28) -> 06 | P28: =IF(C28="",P27,C28) -> 01 | Q28: =IF(D28="",Q27,D28) -> 01 | R28: =CONCATENATE(P28,Q28) -> 0101 | S28: =CONCATENATE(O28,P28,Q28) -> 060101 | U28: =VALUE(S28) -> 60101 | X28: الف ناحیه 1 منطقه 6
A29: =+S29 -> 060102 | C29: 01 | D29: 02 | E29: ب ناحیه 1 منطقه 6 - 9809 | F29: 188349 | I29: 0 | O29: =IF(B29="",O28,B29) -> 06 | P29: =IF(C29="",P28,C29) -> 01 | Q29: =IF(D29="",Q28,D29) -> 02 | R29: =CONCATENATE(P29,Q29) -> 0102 | S29: =CONCATENATE(O29,P29,Q29) -> 060102 | U29: =VALUE(S29) -> 60102 | X29: الف ناحیه 2 منطقه 6
A30: =+S30 -> 060201 | C30: 02 | D30: 01 | E30: الف ناحیه 2 منطقه 6 - 9808 | F30: 257661 | G30: 0 | H30: 913612 | I30: 0 | J30: 1049347 | O30: =IF(B30="",O29,B30) -> 06 | P30: =IF(C30="",P29,C30) -> 02 | Q30: =IF(D30="",Q29,D30) -> 01 | R30: =CONCATENATE(P30,Q30) -> 0201 | S30: =CONCATENATE(O30,P30,Q30) -> 060201 | U30: =VALUE(S30) -> 60201 | X30: ب ناحیه 2 منطقه 6
A31: =+S31 -> 060202 | C31: 02 | D31: 02 | E31: ب ناحیه 2 منطقه 6 - 9809 | F31: 106788 | G31: 0 | I31: 0 | O31: =IF(B31="",O30,B31) -> 06 | P31: =IF(C31="",P30,C31) -> 02 | Q31: =IF(D31="",Q30,D31) -> 02 | R31: =CONCATENATE(P31,Q31) -> 0202 | S31: =CONCATENATE(O31,P31,Q31) -> 060202 | U31: =VALUE(S31) -> 60202 | X31: ناحیه 3 منطقه 6
A32: =+S32 -> 060301 | C32: 03 | D32: 01 | E32: ناحیه 3 منطقه 6 | F32: 132714 | G32: 50000 | H32: 388246 | I32: 0 | J32: 529900 | O32: =IF(B32="",O31,B32) -> 06 | P32: =IF(C32="",P31,C32) -> 03 | Q32: =IF(D32="",Q31,D32) -> 01 | R32: =CONCATENATE(P32,Q32) -> 0301 | S32: =CONCATENATE(O32,P32,Q32) -> 060301 | U32: =VALUE(S32) -> 60301 | X32: الف ناحیه 4 منطقه 6
A33: =+S33 -> 070101 | B33: 07 | C33: 01 | D33: 01 | E33: ناحیه 1 منطقه 7 - 9810 | F33: 397833 | G33: 0 | H33: 126830 | I33: 0 | J33: 948569 | O33: =IF(B33="",O32,B33) -> 07 | P33: =IF(C33="",P32,C33) -> 01 | Q33: =IF(D33="",Q32,D33) -> 01 | R33: =CONCATENATE(P33,Q33) -> 0101 | S33: =CONCATENATE(O33,P33,Q33) -> 070101 | U33: =VALUE(S33) -> 70101 | X33: ناحیه 1 منطقه 7
